Workbook

Sheet Compare
A1: PriceHub — Compare One Product on 3 Marketplaces
A2: Collected data (15-17 Oct 2026), not live. The best marketplace is calculated each time from price, warranty and rating. Nothing is stored in advance.
A4: Select a product: | B4: Wireless Bluetooth Neckband Earphones
A5: ="Weights in use: price "&TEXT(Weights!$B$5,"0%")&", rating "&TEXT(Weights!$B$6,"0%")&", warranty "&TEXT(Weights!$B$7,"0%")&" (change them on the Weights sheet)" -> Weights in use: price 50%, rating 30%, warranty 20% (change them on the Weights sheet)
A7: Marketplace | B7: Price (₹) | C7: Warranty (as collected) | D7: Warranty (months) | E7: Rating (out of 5) | F7: In stock | G7: Price date | H7: Price score | I7: Rating score | J7: Warranty score | K7: Value score (0-100) | L7: Rank | M7: Price rank
A8: Amazon | B8: =IFERROR(INDEX(Products!$E$5:$E$60,MATCH($B$4&"|"&$A8,Products!$W$5:$W$60,0)),"Not listed") -> 379 | C8: =IFERROR(INDEX(Products!$F$5:$F$60,MATCH($B$4&"|"&$A8,Products!$W$5:$W$60,0)),"Not listed") -> 1 Year | D8: =IFERROR(INDEX(Products!$M$5:$M$60,MATCH($B$4&"|"&$A8,Products!$W$5:$W$60,0)),"Not listed") -> 12 | E8: =IFERROR(INDEX(Products!$G$5:$G$60,MATCH($B$4&"|"&$A8,Products!$W$5:$W$60,0)),"Not listed") -> 3.7 | F8: =IFERROR(INDEX(Products!$H$5:$H$60,MATCH($B$4&"|"&$A8,Products!$W$5:$W$60,0)),"Not listed") -> Yes | G8: =IFERROR(INDEX(Products!$I$5:$I$60,MATCH($B$4&"|"&$A8,Products!$W$5:$W$60,0)),"Not listed") -> 46310 | H8: =IFERROR(INDEX(Products!$N$5:$N$60,MATCH($B$4&"|"&$A8,Products!$W$5:$W$60,0)),"Not listed") -> 0.76809453 | I8: =IFERROR(INDEX(Products!$O$5:$O$60,MATCH($B$4&"|"&$A8,Products!$W$5:$W$60,0)),"Not listed") -> 0.74 | J8: =IFERROR(INDEX(Products!$P$5:$P$60,MATCH($B$4&"|"&$A8,Products!$W$5:$W$60,0)),"Not listed") -> 1 | K8: =IFERROR(INDEX(Products!$R$5:$R$60,MATCH($B$4&"|"&$A8,Products!$W$5:$W$60,0)),"Not listed") -> 80.6 | L8: =IFERROR(INDEX(Products!$S$5:$S$60,MATCH($B$4&"|"&$A8,Products!$W$5:$W$60,0)),"Not listed") -> 1 | M8: =IFERROR(INDEX(Products!$T$5:$T$60,MATCH($B$4&"|"&$A8,Products!$W$5:$W$60,0)),"Not listed") -> 2
A9: Flipkart | B9: =IFERROR(INDEX(Products!$E$5:$E$60,MATCH($B$4&"|"&$A9,Products!$W$5:$W$60,0)),"Not listed") -> 899 | C9: =IFERROR(INDEX(Products!$F$5:$F$60,MATCH($B$4&"|"&$A9,Products!$W$5:$W$60,0)),"Not listed") -> 1 Year | D9: =IFERROR(INDEX(Products!$M$5:$M$60,MATCH($B$4&"|"&$A9,Products!$W$5:$W$60,0)),"Not listed") -> 12 | E9: =IFERROR(INDEX(Products!$G$5:$G$60,MATCH($B$4&"|"&$A9,Products!$W$5:$W$60,0)),"Not listed") -> 4.2 | F9: =IFERROR(INDEX(Products!$H$5:$H$60,MATCH($B$4&"|"&$A9,Products!$W$5:$W$60,0)),"Not listed") -> Yes | G9: =IFERROR(INDEX(Products!$I$5:$I$60,MATCH($B$4&"|"&$A9,Products!$W$5:$W$60,0)),"Not listed") -> 46310 | H9: =IFERROR(INDEX(Products!$N$5:$N$60,MATCH($B$4&"|"&$A9,Products!$W$5:$W$60,0)),"Not listed") -> 0 | I9: =IFERROR(INDEX(Products!$O$5:$O$60,MATCH($B$4&"|"&$A9,Products!$W$5:$W$60,0)),"Not listed") -> 0.84 | J9: =IFERROR(INDEX(Products!$P$5:$P$60,MATCH($B$4&"|"&$A9,Products!$W$5:$W$60,0)),"Not listed") -> 1 | K9: =IFERROR(INDEX(Products!$R$5:$R$60,MATCH($B$4&"|"&$A9,Products!$W$5:$W$60,0)),"Not listed") -> 45.2 | L9: =IFERROR(INDEX(Products!$S$5:$S$60,MATCH($B$4&"|"&$A9,Products!$W$5:$W$60,0)),"Not listed") -> 3 | M9: =IFERROR(INDEX(Products!$T$5:$T$60,MATCH($B$4&"|"&$A9,Products!$W$5:$W$60,0)),"Not listed") -> 3
A10: Meesho | B10: =IFERROR(INDEX(Products!$E$5:$E$60,MATCH($B$4&"|"&$A10,Products!$W$5:$W$60,0)),"Not listed") -> 222 | C10: =IFERROR(INDEX(Products!$F$5:$F$60,MATCH($B$4&"|"&$A10,Products!$W$5:$W$60,0)),"Not listed") -> No Warranty | D10: =IFERROR(INDEX(Products!$M$5:$M$60,MATCH($B$4&"|"&$A10,Products!$W$5:$W$60,0)),"Not listed") -> 0 | E10: =IFERROR(INDEX(Products!$G$5:$G$60,MATCH($B$4&"|"&$A10,Products!$W$5:$W$60,0)),"Not listed") -> 3.9 | F10: =IFERROR(INDEX(Products!$H$5:$H$60,MATCH($B$4&"|"&$A10,Products!$W$5:$W$60,0)),"Not listed") -> Yes | G10: =IFERROR(INDEX(Products!$I$5:$I$60,MATCH($B$4&"|"&$A10,Products!$W$5:$W$60,0)),"Not listed") -> 46310 | H10: =IFERROR(INDEX(Products!$N$5:$N$60,MATCH($B$4&"|"&$A10,Products!$W$5:$W$60,0)),"Not listed") -> 1 | I10: =IFERROR(INDEX(Products!$O$5:$O$60,MATCH($B$4&"|"&$A10,Products!$W$5:$W$60,0)),"Not listed") -> 0.78 | J10: =IFERROR(INDEX(Products!$P$5:$P$60,MATCH($B$4&"|"&$A10,Products!$W$5:$W$60,0)),"Not listed") -> 0 | K10: =IFERROR(INDEX(Products!$R$5:$R$60,MATCH($B$4&"|"&$A10,Products!$W$5:$W$60,0)),"Not listed") -> 73.4 | L10: =IFERROR(INDEX(Products!$S$5:$S$60,MATCH($B$4&"|"&$A10,Products!$W$5:$W$60,0)),"Not listed") -> 2 | M10: =IFERROR(INDEX(Products!$T$5:$T$60,MATCH($B$4&"|"&$A10,Products!$W$5:$W$60,0)),"Not listed") -> 1
A12: Best value: | B12: =IFERROR(INDEX($A$8:$A$10,MATCH(1,$L$8:$L$10,0)),"No in-stock listing") -> Amazon
A13: Price there (₹): | B13: =IFERROR(INDEX($B$8:$B$10,MATCH(1,$L$8:$L$10,0)),"") -> 379
A14: Lowest in-stock price on: | B14: =IFERROR(INDEX($A$8:$A$10,MATCH(1,$M$8:$M$10,0)),"") -> Meesho
A15: Lowest in-stock price (₹): | B15: =IFERROR(INDEX($B$8:$B$10,MATCH(1,$M$8:$M$10,0)),"") -> 222
A16: Why: | B16: =IF($B$12="No in-stock listing","No marketplace has this product in stock.",IF(OR($B$12=$B$14,$B$13=$B$15),$B$12&" is the best value: lowest in-stock price"&IF(COUNT($B$8:$B$10)>1," and the best overall score on price, warranty and rating.","."),$B$12&" is the best value. "&$B$14&" is cheaper by ₹"&TEXT($B$13-$B$15,"#,##0")&", but scores lower overall on price, warranty and rating.")) -> Amazon is the best value. Meesho is cheaper by ₹157, but scores lower overall on price, warranty and rating.
A18: Links and images for each listing are on the 'Products' sheet (columns K and L). Warranty is converted to months from your text. Out-of-stock listings are excluded from the ranking.

Sheet Overview
A1: PriceHub — Overview: best marketplace for each product (15 similar products × 3 marketplaces)
A2: Calculated live from 'Products' and 'Weights'. Nothing here is stored. Collected 15-17 Oct 2026; not live. Items are similar, not identical, products.
A4: Product ID | B4: Product | C4: Category | D4: Best-value marketplace | E4: Price there (₹) | F4: Value score (0-100) | G4: Lowest-price marketplace | H4: Lowest price (₹) | I4: Extra cost vs lowest (₹) | J4: Recommendation | K4: Other similar products in category | L4: Helper: category key
A5: 1 | B5: =IF($A5="","",INDEX(Products!$B$5:$B$60,MATCH($A5,Products!$A$5:$A$60,0))) -> Wireless Bluetooth Neckband Earphones | C5: =IF($A5="","",INDEX(Products!$C$5:$C$60,MATCH($A5,Products!$A$5:$A$60,0))) -> Audio | D5: =IF($A5="","",IFERROR(INDEX(Products!$D$5:$D$60,MATCH($A5&"|1",Products!$U$5:$U$60,0)),"No in-stock listing")) -> Amazon | E5: =IF(OR($A5="",$D5="No in-stock listing"),"",INDEX(Products!$E$5:$E$60,MATCH($A5&"|1",Products!$U$5:$U$60,0))) -> 379 | F5: =IF(OR($A5="",$D5="No in-stock listing"),"",INDEX(Products!$R$5:$R$60,MATCH($A5&"|1",Products!$U$5:$U$60,0))) -> 80.6 | G5: =IF(OR($A5="",$D5="No in-stock listing"),"",INDEX(Products!$D$5:$D$60,MATCH($A5&"|1",Products!$V$5:$V$60,0))) -> Meesho | H5: =IF(OR($A5="",$D5="No in-stock listing"),"",INDEX(Products!$E$5:$E$60,MATCH($A5&"|1",Products!$V$5:$V$60,0))) -> 222 | I5: =IF($E5="","",$E5-$H5) -> 157 | J5: =IF($A5="","",IF($D5="No in-stock listing","No in-stock listing for this product.",IF(OR($D5=$G5,$I5=0),$D5&": lowest in-stock price and best overall value.",$D5&" is the best value. "&$G5&" is cheaper by ₹"&TEXT($I5,"#,##0")&" but scores lower overall across the weighted factors."))) -> Amazon is the best value. Meesho is cheaper by ₹157 but scores lower overall across the weighted factors. | K5: =IF($A5="","",COUNTIF($C$5:$C$19,$C5)-1) -> 2 | L5: =IF(OR($A5="",$E5=""),"",$C5&"|"&$E5) -> Audio|379
A6: 2 | B6: =IF($A6="","",INDEX(Products!$B$5:$B$60,MATCH($A6,Products!$A$5:$A$60,0))) -> True Wireless Earbuds with Charging Case | C6: =IF($A6="","",INDEX(Products!$C$5:$C$60,MATCH($A6,Products!$A$5:$A$60,0))) -> Audio | D6: =IF($A6="","",IFERROR(INDEX(Products!$D$5:$D$60,MATCH($A6&"|1",Products!$U$5:$U$60,0)),"No in-stock listing")) -> Meesho | E6: =IF(OR($A6="",$D6="No in-stock listing"),"",INDEX(Products!$E$5:$E$60,MATCH($A6&"|1",Products!$U$5:$U$60,0))) -> 581 | F6: =IF(OR($A6="",$D6="No in-stock listing"),"",INDEX(Products!$R$5:$R$60,MATCH($A6&"|1",Products!$U$5:$U$60,0))) -> 74.6 | G6: =IF(OR($A6="",$D6="No in-stock listing"),"",INDEX(Products!$D$5:$D$60,MATCH($A6&"|1",Products!$V$5:$V$60,0))) -> Meesho | H6: =IF(OR($A6="",$D6="No in-stock listing"),"",INDEX(Products!$E$5:$E$60,MATCH($A6&"|1",Products!$V$5:$V$60,0))) -> 581 | I6: =IF($E6="","",$E6-$H6) -> 0 | J6: =IF($A6="","",IF($D6="No in-stock listing","No in-stock listing for this product.",IF(OR($D6=$G6,$I6=0),$D6&": lowest in-stock price and best overall value.",$D6&" is the best value. "&$G6&" is cheaper by ₹"&TEXT($I6,"#,##0")&" but scores lower overall across the weighted factors."))) -> Meesho: lowest in-stock price and best overall value. | K6: =IF($A6="","",COUNTIF($C$5:$C$19,$C6)-1) -> 2 | L6: =IF(OR($A6="",$E6=""),"",$C6&"|"&$E6) -> Audio|581
A7: 3 | B7: =IF($A7="","",INDEX(Products!$B$5:$B$60,MATCH($A7,Products!$A$5:$A$60,0))) -> Wired In-Ear Earphones with Mic | C7: =IF($A7="","",INDEX(Products!$C$5:$C$60,MATCH($A7,Products!$A$5:$A$60,0))) -> Audio | D7: =IF($A7="","",IFERROR(INDEX(Products!$D$5:$D$60,MATCH($A7&"|1",Products!$U$5:$U$60,0)),"No in-stock listing")) -> Amazon | E7: =IF(OR($A7="",$D7="No in-stock listing"),"",INDEX(Products!$E$5:$E$60,MATCH($A7&"|1",Products!$U$5:$U$60,0))) -> 94 | F7: =IF(OR($A7="",$D7="No in-stock listing"),"",INDEX(Products!$R$5:$R$60,MATCH($A7&"|1",Products!$U$5:$U$60,0))) -> 89.8 | G7: =IF(OR($A7="",$D7="No in-stock listing"),"",INDEX(Products!$D$5:$D$60,MATCH($A7&"|1",Products!$V$5:$V$60,0))) -> Amazon | H7: =IF(OR($A7="",$D7="No in-stock listing"),"",INDEX(Products!$E$5:$E$60,MATCH($A7&"|1",Products!$V$5:$V$60,0))) -> 94 | I7: =IF($E7="","",$E7-$H7) -> 0 | J7: =IF($A7="","",IF($D7="No in-stock listing","No in-stock listing for this product.",IF(OR($D7=$G7,$I7=0),$D7&": lowest in-stock price and best overall value.",$D7&" is the best value. "&$G7&" is cheaper by ₹"&TEXT($I7,"#,##0")&" but scores lower overall across the weighted factors."))) -> Amazon: lowest in-stock price and best overall value. | K7: =IF($A7="","",COUNTIF($C$5:$C$19,$C7)-1) -> 2 | L7: =IF(OR($A7="",$E7=""),"",$C7&"|"&$E7) -> Audio|94
A8: 4 | B8: =IF($A8="","",INDEX(Products!$B$5:$B$60,MATCH($A8,Products!$A$5:$A$60,0))) -> Women's Cotton Churidar Set | C8: =IF($A8="","",INDEX(Products!$C$5:$C$60,MATCH($A8,Products!$A$5:$A$60,0))) -> Clothing | D8: =IF($A8="","",IFERROR(INDEX(Products!$D$5:$D$60,MATCH($A8&"|1",Products!$U$5:$U$60,0)),"No in-stock listing")) -> Meesho | E8: =IF(OR($A8="",$D8="No in-stock listing"),"",INDEX(Products!$E$5:$E$60,MATCH($A8&"|1",Products!$U$5:$U$60,0))) -> 376 | F8: =IF(OR($A8="",$D8="No in-stock listing"),"",INDEX(Products!$R$5:$R$60,MATCH($A8&"|1",Products!$U$5:$U$60,0))) -> 97 | G8: =IF(OR($A8="",$D8="No in-stock listing"),"",INDEX(Products!$D$5:$D$60,MATCH($A8&"|1",Products!$V$5:$V$60,0))) -> Meesho | H8: =IF(OR($A8="",$D8="No in-stock listing"),"",INDEX(Products!$E$5:$E$60,MATCH($A8&"|1",Products!$V$5:$V$60,0))) -> 376 | I8: =IF($E8="","",$E8-$H8) -> 0 | J8: =IF($A8="","",IF($D8="No in-stock listing","No in-stock listing for this product.",IF(OR($D8=$G8,$I8=0),$D8&": lowest in-stock price and best overall value.",$D8&" is the best value. "&$G8&" is cheaper by ₹"&TEXT($I8,"#,##0")&" but scores lower overall across the weighted factors."))) -> Meesho: lowest in-stock price and best overall value. | K8: =IF($A8="","",COUNTIF($C$5:$C$19,$C8)-1) -> 4 | L8: =IF(OR($A8="",$E8=""),"",$C8&"|"&$E8) -> Clothing|376
A9: 5 | B9: =IF($A9="","",INDEX(Products!$B$5:$B$60,MATCH($A9,Products!$A$5:$A$60,0))) -> Girls Cotton Party Frock | C9: =IF($A9="","",INDEX(Products!$C$5:$C$60,MATCH($A9,Products!$A$5:$A$60,0))) -> Clothing | D9: =IF($A9="","",IFERROR(INDEX(Products!$D$5:$D$60,MATCH($A9&"|1",Products!$U$5:$U$60,0)),"No in-stock listing")) -> Meesho | E9: =IF(OR($A9="",$D9="No in-stock listing"),"",INDEX(Products!$E$5:$E$60,MATCH($A9&"|1",Products!$U$5:$U$60,0))) -> 247 | F9: =IF(OR($A9="",$D9="No in-stock listing"),"",INDEX(Products!$R$5:$R$60,MATCH($A9&"|1",Products!$U$5:$U$60,0))) -> 97 | G9: =IF(OR($A9="",$D9="No in-stock listing"),"",INDEX(Products!$D$5:$D$60,MATCH($A9&"|1",Products!$V$5:$V$60,0))) -> Meesho | H9: =IF(OR($A9="",$D9="No in-stock listing"),"",INDEX(Products!$E$5:$E$60,MATCH($A9&"|1",Products!$V$5:$V$60,0))) -> 247 | I9: =IF($E9="","",$E9-$H9) -> 0 | J9: =IF($A9="","",IF($D9="No in-stock listing","No in-stock listing for this product.",IF(OR($D9=$G9,$I9=0),$D9&": lowest in-stock price and best overall value.",$D9&" is the best value. "&$G9&" is cheaper by ₹"&TEXT($I9,"#,##0")&" but scores lower overall across the weighted factors."))) -> Meesho: lowest in-stock price and best overall value. | K9: =IF($A9="","",COUNTIF($C$5:$C$19,$C9)-1) -> 4 | L9: =IF(OR($A9="",$E9=""),"",$C9&"|"&$E9) -> Clothing|247
A10: 6 | B10: =IF($A10="","",INDEX(Products!$B$5:$B$60,MATCH($A10,Products!$A$5:$A$60,0))) -> Women's Anarkali Kurti Set | C10: =IF($A10="","",INDEX(Products!$C$5:$C$60,MATCH($A10,Products!$A$5:$A$60,0))) -> Clothing | D10: =IF($A10="","",IFERROR(INDEX(Products!$D$5:$D$60,MATCH($A10&"|1",Products!$U$5:$U$60,0)),"No in-stock listing")) -> Meesho | E10: =IF(OR($A10="",$D10="No in-stock listing"),"",INDEX(Products!$E$5:$E$60,MATCH($A10&"|1",Products!$U$5:$U$60,0))) -> 740 | F10: =IF(OR($A10="",$D10="No in-stock listing"),"",INDEX(Products!$R$5:$R$60,MATCH($A10&"|1",Products!$U$5:$U$60,0))) -> 100 | G10: =IF(OR($A10="",$D10="No in-stock listing"),"",INDEX(Products!$D$5:$D$60,MATCH($A10&"|1",Products!$V$5:$V$60,0))) -> Meesho | H10: =IF(OR($A10="",$D10="No in-stock listing"),"",INDEX(Products!$E$5:$E$60,MATCH($A10&"|1",Products!$V$5:$V$60,0))) -> 740 | I10: =IF($E10="","",$E10-$H10) -> 0 | J10: =IF($A10="","",IF($D10="No in-stock listing","No in-stock listing for this product.",IF(OR($D10=$G10,$I10=0),$D10&": lowest in-stock price and best overall value.",$D10&" is the best value. "&$G10&" is cheaper by ₹"&TEXT($I10,"#,##0")&" but scores lower overall across the weighted factors."))) -> Meesho: lowest in-stock price and best overall value. | K10: =IF($A10="","",COUNTIF($C$5:$C$19,$C10)-1) -> 4 | L10: =IF(OR($A10="",$E10=""),"",$C10&"|"&$E10) -> Clothing|740
A11: 7 | B11: =IF($A11="","",INDEX(Products!$B$5:$B$60,MATCH($A11,Products!$A$5:$A$60,0))) -> Women's Floral Print Maxi Dress | C11: =IF($A11="","",INDEX(Products!$C$5:$C$60,MATCH($A11,Products!$A$5:$A$60,0))) -> Clothing | D11: =IF($A11="","",IFERROR(INDEX(Products!$D$5:$D$60,MATCH($A11&"|1",Products!$U$5:$U$60,0)),"No in-stock listing")) -> Amazon | E11: =IF(OR($A11="",$D11="No in-stock listing"),"",INDEX(Products!$E$5:$E$60,MATCH($A11&"|1",Products!$U$5:$U$60,0))) -> 288 | F11: =IF(OR($A11="",$D11="No in-stock listing"),"",INDEX(Products!$R$5:$R$60,MATCH($A11&"|1",Products!$U$5:$U$60,0))) -> 92.8 | G11: =IF(OR($A11="",$D11="No in-stock listing"),"",INDEX(Products!$D$5:$D$60,MATCH($A11&"|1",Products!$V$5:$V$60,0))) -> Amazon | H11: =IF(OR($A11="",$D11="No in-stock listing"),"",INDEX(Products!$E$5:$E$60,MATCH($A11&"|1",Products!$V$5:$V$60,0))) -> 288 | I11: =IF($E11="","",$E11-$H11) -> 0 | J11: =IF($A11="","",IF($D11="No in-stock listing","No in-stock listing for this product.",IF(OR($D11=$G11,$I11=0),$D11&": lowest in-stock price and best overall value.",$D11&" is the best value. "&$G11&" is cheaper by ₹"&TEXT($I11,"#,##0")&" but scores lower overall across the weighted factors."))) -> Amazon: lowest in-stock price and best overall value. | K11: =IF($A11="","",COUNTIF($C$5:$C$19,$C11)-1) -> 4 | L11: =IF(OR($A11="",$E11=""),"",$C11&"|"&$E11) -> Clothing|288
A12: 8 | B12: =IF($A12="","",INDEX(Products!$B$5:$B$60,MATCH($A12,Products!$A$5:$A$60,0))) -> Men's Cotton Round Neck T-Shirt | C12: =IF($A12="","",INDEX(Products!$C$5:$C$60,MATCH($A12,Products!$A$5:$A$60,0))) -> Clothing | D12: =IF($A12="","",IFERROR(INDEX(Products!$D$5:$D$60,MATCH($A12&"|1",Products!$U$5:$U$60,0)),"No in-stock listing")) -> Flipkart | E12: =IF(OR($A12="",$D12="No in-stock listing"),"",INDEX(Products!$E$5:$E$60,MATCH($A12&"|1",Products!$U$5:$U$60,0))) -> 400 | F12: =IF(OR($A12="",$D12="No in-stock listing"),"",INDEX(Products!$R$5:$R$60,MATCH($A12&"|1",Products!$U$5:$U$60,0))) -> 95.8 | G12: =IF(OR($A12="",$D12="No in-stock listing"),"",INDEX(Products!$D$5:$D$60,MATCH($A12&"|1",Products!$V$5:$V$60,0))) -> Flipkart | H12: =IF(OR($A12="",$D12="No in-stock listing"),"",INDEX(Products!$E$5:$E$60,MATCH($A12&"|1",Products!$V$5:$V$60,0))) -> 400 | I12: =IF($E12="","",$E12-$H12) -> 0 | J12: =IF($A12="","",IF($D12="No in-stock listing","No in-stock listing for this product.",IF(OR($D12=$G12,$I12=0),$D12&": lowest in-stock price and best overall value.",$D12&" is the best value. "&$G12&" is cheaper by ₹"&TEXT($I12,"#,##0")&" but scores lower overall across the weighted factors."))) -> Flipkart: lowest in-stock price and best overall value. | K12: =IF($A12="","",COUNTIF($C$5:$C$19,$C12)-1) -> 4 | L12: =IF(OR($A12="",$E12=""),"",$C12&"|"&$E12) -> Clothing|400
A13: 9 | B13: =IF($A13="","",INDEX(Products!$B$5:$B$60,MATCH($A13,Products!$A$5:$A$60,0))) -> Men's Running Sports Shoes | C13: =IF($A13="","",INDEX(Products!$C$5:$C$60,MATCH($A13,Products!$A$5:$A$60,0))) -> Footwear | D13: =IF($A13="","",IFERROR(INDEX(Products!$D$5:$D$60,MATCH($A13&"|1",Products!$U$5:$U$60,0)),"No in-stock listing")) -> Meesho | E13: =IF(OR($A13="",$D13="No in-stock listing"),"",INDEX(Products!$E$5:$E$60,MATCH($A13&"|1",Products!$U$5:$U$60,0))) -> 249 | F13: =IF(OR($A13="",$D13="No in-stock listing"),"",INDEX(Products!$R$5:$R$60,MATCH($A13&"|1",Products!$U$5:$U$60,0))) -> 92.2 | G13: =IF(OR($A13="",$D13="No in-stock listing"),"",INDEX(Products!$D$5:$D$60,MATCH($A13&"|1",Products!$V$5:$V$60,0))) -> Meesho | H13: =IF(OR($A13="",$D13="No in-stock listing"),"",INDEX(Products!$E$5:$E$60,MATCH($A13&"|1",Products!$V$5:$V$60,0))) -> 249 | I13: =IF($E13="","",$E13-$H13) -> 0 | J13: =IF($A13="","",IF($D13="No in-stock listing","No in-stock listing for this product.",IF(OR($D13=$G13,$I13=0),$D13&": lowest in-stock price and best overall value.",$D13&" is the best value. "&$G13&" is cheaper by ₹"&TEXT($I13,"#,##0")&" but scores lower overall across the weighted factors."))) -> Meesho: lowest in-stock price and best overall value. | K13: =IF($A13="","",COUNTIF($C$5:$C$19,$C13)-1) -> 1 | L13: =IF(OR($A13="",$E13=""),"",$C13&"|"&$E13) -> Footwear|249
A14: 10 | B14: =IF($A14="","",INDEX(Products!$B$5:$B$60,MATCH($A14,Products!$A$5:$A$60,0))) -> Women's Flat Sandals | C14: =IF($A14="","",INDEX(Products!$C$5:$C$60,MATCH($A14,Products!$A$5:$A$60,0))) -> Footwear | D14: =IF($A14="","",IFERROR(INDEX(Products!$D$5:$D$60,MATCH($A14&"|1",Products!$U$5:$U$60,0)),"No in-stock listing")) -> Meesho | E14: =IF(OR($A14="",$D14="No in-stock listing"),"",INDEX(Products!$E$5:$E$60,MATCH($A14&"|1",Products!$U$5:$U$60,0))) -> 150 | F14: =IF(OR($A14="",$D14="No in-stock listing"),"",INDEX(Products!$R$5:$R$60,MATCH($A14&"|1",Products!$U$5:$U$60,0))) -> 94 | G14: =IF(OR($A14="",$D14="No in-stock listing"),"",INDEX(Products!$D$5:$D$60,MATCH($A14&"|1",Products!$V$5:$V$60,0))) -> Meesho | H14: =IF(OR($A14="",$D14="No in-stock listing"),"",INDEX(Products!$E$5:$E$60,MATCH($A14&"|1",Products!$V$5:$V$60,0))) -> 150 | I14: =IF($E14="","",$E14-$H14) -> 0 | J14: =IF($A14="","",IF($D14="No in-stock listing","No in-stock listing for this product.",IF(OR($D14=$G14,$I14=0),$D14&": lowest in-stock price and best overall value.",$D14&" is the best value. "&$G14&" is cheaper by ₹"&TEXT($I14,"#,##0")&" but scores lower overall across the weighted factors."))) -> Meesho: lowest in-stock price and best overall value. | K14: =IF($A14="","",COUNTIF($C$5:$C$19,$C14)-1) -> 1 | L14: =IF(OR($A14="",$E14=""),"",$C14&"|"&$E14) -> Footwear|150
A15: 11 | B15: =IF($A15="","",INDEX(Products!$B$5:$B$60,MATCH($A15,Products!$A$5:$A$60,0))) -> Women's Analog Wrist Watch Metal Strap | C15: =IF($A15="","",INDEX(Products!$C$5:$C$60,MATCH($A15,Products!$A$5:$A$60,0))) -> Watches | D15: =IF($A15="","",IFERROR(INDEX(Products!$D$5:$D$60,MATCH($A15&"|1",Products!$U$5:$U$60,0)),"No in-stock listing")) -> Amazon | E15: =IF(OR($A15="",$D15="No in-stock listing"),"",INDEX(Products!$E$5:$E$60,MATCH($A15&"|1",Products!$U$5:$U$60,0))) -> 1995 | F15: =IF(OR($A15="",$D15="No in-stock listing"),"",INDEX(Products!$R$5:$R$60,MATCH($A15&"|1",Products!$U$5:$U$60,0))) -> 94.6 | G15: =IF(OR($A15="",$D15="No in-stock listing"),"",INDEX(Products!$D$5:$D$60,MATCH($A15&"|1",Products!$V$5:$V$60,0))) -> Amazon | H15: =IF(OR($A15="",$D15="No in-stock listing"),"",INDEX(Products!$E$5:$E$60,MATCH($A15&"|1",Products!$V$5:$V$60,0))) -> 1995 | I15: =IF($E15="","",$E15-$H15) -> 0 | J15: =IF($A15="","",IF($D15="No in-stock listing","No in-stock listing for this product.",IF(OR($D15=$G15,$I15=0),$D15&": lowest in-stock price and best overall value.",$D15&" is the best value. "&$G15&" is cheaper by ₹"&TEXT($I15,"#,##0")&" but scores lower overall across the weighted factors."))) -> Amazon: lowest in-stock price and best overall value. | K15: =IF($A15="","",COUNTIF($C$5:$C$19,$C15)-1) -> 1 | L15: =IF(OR($A15="",$E15=""),"",$C15&"|"&$E15) -> Watches|1995
A16: 12 | B16: =IF($A16="","",INDEX(Products!$B$5:$B$60,MATCH($A16,Products!$A$5:$A$60,0))) -> Men's Digital Sports Watch | C16: =IF($A16="","",INDEX(Products!$C$5:$C$60,MATCH($A16,Products!$A$5:$A$60,0))) -> Watches | D16: =IF($A16="","",IFERROR(INDEX(Products!$D$5:$D$60,MATCH($A16&"|1",Products!$U$5:$U$60,0)),"No in-stock listing")) -> Amazon | E16: =IF(OR($A16="",$D16="No in-stock listing"),"",INDEX(Products!$E$5:$E$60,MATCH($A16&"|1",Products!$U$5:$U$60,0))) -> 260 | F16: =IF(OR($A16="",$D16="No in-stock listing"),"",INDEX(Products!$R$5:$R$60,MATCH($A16&"|1",Products!$U$5:$U$60,0))) -> 71 | G16: =IF(OR($A16="",$D16="No in-stock listing"),"",INDEX(Products!$D$5:$D$60,MATCH($A16&"|1",Products!$V$5:$V$60,0))) -> Amazon | H16: =IF(OR($A16="",$D16="No in-stock listing"),"",INDEX(Products!$E$5:$E$60,MATCH($A16&"|1",Products!$V$5:$V$60,0))) -> 260 | I16: =IF($E16="","",$E16-$H16) -> 0 | J16: =IF($A16="","",IF($D16="No in-stock listing","No in-stock listing for this product.",IF(OR($D16=$G16,$I16=0),$D16&": lowest in-stock price and best overall value.",$D16&" is the best value. "&$G16&" is cheaper by ₹"&TEXT($I16,"#,##0")&" but scores lower overall across the weighted factors."))) -> Amazon: lowest in-stock price and best overall value. | K16: =IF($A16="","",COUNTIF($C$5:$C$19,$C16)-1) -> 1 | L16: =IF(OR($A16="",$E16=""),"",$C16&"|"&$E16) -> Watches|260
... A19: 15 | B19: =IF($A19="","",INDEX(Products!$B$5:$B$60,MATCH($A19,Products!$A$5:$A$60,0))) -> Kids Cycle | C19: =IF($A19="","",INDEX(Products!$C$5:$C$60,MATCH($A19,Products!$A$5:$A$60,0))) -> Kids | D19: =IF($A19="","",IFERROR(INDEX(Products!$D$5:$D$60,MATCH($A19&"|1",Products!$U$5:$U$60,0)),"No in-stock listing")) -> Meesho | E19: =IF(OR($A19="",$D19="No in-stock listing"),"",INDEX(Products!$E$5:$E$60,MATCH($A19&"|1",Products!$U$5:$U$60,0))) -> 700 | F19: =IF(OR($A19="",$D19="No in-stock listing"),"",INDEX(Products!$R$5:$R$60,MATCH($A19&"|1",Products!$U$5:$U$60,0))) -> 92.8 | G19: =IF(OR($A19="",$D19="No in-stock listing"),"",INDEX(Products!$D$5:$D$60,MATCH($A19&"|1",Products!$V$5:$V$60,0))) -> Meesho | H19: =IF(OR($A19="",$D19="No in-stock listing"),"",INDEX(Products!$E$5:$E$60,MATCH($A19&"|1",Products!$V$5:$V$60,0))) -> 700 | I19: =IF($E19="","",$E19-$H19) -> 0 | J19: =IF($A19="","",IF($D19="No in-stock listing","No in-stock listing for this product.",IF(OR($D19=$G19,$I19=0),$D19&": lowest in-stock price and best overall value.",$D19&" is the best value. "&$G19&" is cheaper by ₹"&TEXT($I19,"#,##0")&" but scores lower overall across the weighted factors."))) -> Meesho: lowest in-stock price and best overall value. | K19: =IF($A19="","",COUNTIF($C$5:$C$19,$C19)-1) -> 0 | L19: =IF(OR($A19="",$E19=""),"",$C19&"|"&$E19) -> Kids|700

Sheet Products
A1: PriceHub — Product Prices (similar products on Amazon, Flipkart, Meesho)
A2: Values you collected (prices.csv, dated 15-17 Oct 2026). Not live data. Items are similar products, not identical models.
A3: Blue = you edit. Black = formula. Green rows = best-value listing for that product (calculated, not stored).
A4: Product ID | B4: Product | C4: Category | D4: Marketplace | E4: Price (₹) | F4: Warranty (as collected) | G4: Rating (out of 5) | H4: In stock (Yes/No) | I4: Price date | J4: Delivery (days, optional) | K4: Product link | L4: Image link | M4: Warranty (months) | N4: Price score | O4: Rating score | P4: Warranty score | Q4: Delivery score | R4: Value score (0-100) | S4: Rank in product | T4: Price rank | U4: Helper: best key | V4: Helper: price key | W4: Helper: product|marketplace
A5: 1 | B5: Wireless Bluetooth Neckband Earphones | C5: Audio | D5: Amazon | E5: 379 | F5: 1 Year | G5: 3.7 | H5: Yes | I5: 46310 | K5: Open | L5: Image | M5: =IF($F5="","",IF(ISNUMBER(SEARCH("no warranty",$F5)),0,IF(ISNUMBER(SEARCH("year",$F5)),12*VALUE(LEFT($F5,FIND(" ",$F5)-1)),IF(ISNUMBER(SEARCH("month",$F5)),VALUE(LEFT($F5,FIND(" ",$F5)-1)),"")))) -> 12 | N5: =IF(OR($H5<>"Yes",$E5=""),"",IF(_xlfn.MAXIFS($E$5:$E$60,$A$5:$A$60,$A5,$H$5:$H$60,"Yes")=_xlfn.MINIFS($E$5:$E$60,$A$5:$A$60,$A5,$H$5:$H$60,"Yes"),1,(_xlfn.MAXIFS($E$5:$E$60,$A$5:$A$60,$A5,$H$5:$H$60,"Yes")-$E5)/(_xlfn.MAXIFS($E$5:$E$60,$A$5:$A$60,$A5,$H$5:$H$60,"Yes")-_xlfn.MINIFS($E$5:$E$60,$A$5:$A$60,$A5,$H$5:$H$60,"Yes")))) -> 0.76809453 | O5: =IF(OR($H5<>"Yes",$G5=""),"",IF(Weights!$B$10="Relative",IF(_xlfn.MAXIFS($G$5:$G$60,$A$5:$A$60,$A5,$H$5:$H$60,"Yes")=_xlfn.MINIFS($G$5:$G$60,$A$5:$A$60,$A5,$H$5:$H$60,"Yes"),1,($G5-_xlfn.MINIFS($G$5:$G$60,$A$5:$A$60,$A5,$H$5:$H$60,"Yes"))/(_xlfn.MAXIFS($G$5:$G$60,$A$5:$A$60,$A5,$H$5:$H$60,"Yes")-_xlfn.MINIFS($G$5:$G$60,$A$5:$A$60,$A5,$H$5:$H$60,"Yes"))),$G5/5)) -> 0.74 | P5: =IF(OR($H5<>"Yes",$M5=""),"",IF(_xlfn.MAXIFS($M$5:$M$60,$A$5:$A$60,$A5,$H$5:$H$60,"Yes")=_xlfn.MINIFS($M$5:$M$60,$A$5:$A$60,$A5,$H$5:$H$60,"Yes"),1,($M5-_xlfn.MINIFS($M$5:$M$60,$A$5:$A$60,$A5,$H$5:$H$60,"Yes"))/(_xlfn.MAXIFS($M$5:$M$60,$A$5:$A$60,$A5,$H$5:$H$60,"Yes")-_xlfn.MINIFS($M$5:$M$60,$A$5:$A$60,$A5,$H$5:$H$60,"Yes")))) -> 1 | Q5: =IF(OR($H5<>"Yes",$J5=""),"",IF(_xlfn.MAXIFS($J$5:$J$60,$A$5:$A$60,$A5,$H$5:$H$60,"Yes")=_xlfn.MINIFS($J$5:$J$60,$A$5:$A$60,$A5,$H$5:$H$60,"Yes"),1,(_xlfn.MAXIFS($J$5:$J$60,$A$5:$A$60,$A5,$H$5:$H$60,"Yes")-$J5)/(_xlfn.MAXIFS($J$5:$J$60,$A$5:$A$60,$A5,$H$5:$H$60,"Yes")-_xlfn.MINIFS($J$5:$J$60,$A$5:$A$60,$A5,$H$5:$H$60,"Yes")))) | R5: =IF($H5<>"Yes","",IFERROR(ROUND(100*(IF($N5="",0,Weights!$B$5*$N5)+IF($O5="",0,Weights!$B$6*$O5)+IF($P5="",0,Weights!$B$7*$P5)+IF($Q5="",0,Weights!$B$8*$Q5))/(IF($N5="",0,Weights!$B$5)+IF($O5="",0,Weights!$B$6)+IF($P5="",0,Weights!$B$7)+IF($Q5="",0,Weights!$B$8)),2),"")) -> 80.6 | S5: =IF($R5="","",COUNTIFS($A$5:$A$60,$A5,$R$5:$R$60,">"&$R5)+1) -> 1 | T5: =IF(OR($H5<>"Yes",$E5=""),"",COUNTIFS($A$5:$A$60,$A5,$H$5:$H$60,"Yes",$E$5:$E$60,"<"&$E5)+1) -> 2 | U5: =IF($S5="","",$A5&"|"&$S5) -> 1|1 | V5: =IF($T5="","",$A5&"|"&$T5) -> 1|2 | W5: =IF($B5="","",$B5&"|"&$D5) -> Wireless Bluetooth Neckband Earphones|Amazon
A6: 1 | B6: Wireless Bluetooth Neckband Earphones | C6: Audio | D6: Flipkart | E6: 899 | F6: 1 Year | G6: 4.2 | H6: Yes | I6: 46310 | K6: Open | L6: Image | M6: =IF($F6="","",IF(ISNUMBER(SEARCH("no warranty",$F6)),0,IF(ISNUMBER(SEARCH("year",$F6)),12*VALUE(LEFT($F6,FIND(" ",$F6)-1)),IF(ISNUMBER(SEARCH("month",$F6)),VALUE(LEFT($F6,FIND(" ",$F6)-1)),"")))) -> 12 | N6: =IF(OR($H6<>"Yes",$E6=""),"",IF(_xlfn.MAXIFS($E$5:$E$60,$A$5:$A$60,$A6,$H$5:$H$60,"Yes")=_xlfn.MINIFS($E$5:$E$60,$A$5:$A$60,$A6,$H$5:$H$60,"Yes"),1,(_xlfn.MAXIFS($E$5:$E$60,$A$5:$A$60,$A6,$H$5:$H$60,"Yes")-$E6)/(_xlfn.MAXIFS($E$5:$E$60,$A$5:$A$60,$A6,$H$5:$H$60,"Yes")-_xlfn.MINIFS($E$5:$E$60,$A$5:$A$60,$A6,$H$5:$H$60,"Yes")))) -> 0 | O6: =IF(OR($H6<>"Yes",$G6=""),"",IF(Weights!$B$10="Relative",IF(_xlfn.MAXIFS($G$5:$G$60,$A$5:$A$60,$A6,$H$5:$H$60,"Yes")=_xlfn.MINIFS($G$5:$G$60,$A$5:$A$60,$A6,$H$5:$H$60,"Yes"),1,($G6-_xlfn.MINIFS($G$5:$G$60,$A$5:$A$60,$A6,$H$5:$H$60,"Yes"))/(_xlfn.MAXIFS($G$5:$G$60,$A$5:$A$60,$A6,$H$5:$H$60,"Yes")-_xlfn.MINIFS($G$5:$G$60,$A$5:$A$60,$A6,$H$5:$H$60,"Yes"))),$G6/5)) -> 0.84 | P6: =IF(OR($H6<>"Yes",$M6=""),"",IF(_xlfn.MAXIFS($M$5:$M$60,$A$5:$A$60,$A6,$H$5:$H$60,"Yes")=_xlfn.MINIFS($M$5:$M$60,$A$5:$A$60,$A6,$H$5:$H$60,"Yes"),1,($M6-_xlfn.MINIFS($M$5:$M$60,$A$5:$A$60,$A6,$H$5:$H$60,"Yes"))/(_xlfn.MAXIFS($M$5:$M$60,$A$5:$A$60,$A6,$H$5:$H$60,"Yes")-_xlfn.MINIFS($M$5:$M$60,$A$5:$A$60,$A6,$H$5:$H$60,"Yes")))) -> 1 | Q6: =IF(OR($H6<>"Yes",$J6=""),"",IF(_xlfn.MAXIFS($J$5:$J$60,$A$5:$A$60,$A6,$H$5:$H$60,"Yes")=_xlfn.MINIFS($J$5:$J$60,$A$5:$A$60,$A6,$H$5:$H$60,"Yes"),1,(_xlfn.MAXIFS($J$5:$J$60,$A$5:$A$60,$A6,$H$5:$H$60,"Yes")-$J6)/(_xlfn.MAXIFS($J$5:$J$60,$A$5:$A$60,$A6,$H$5:$H$60,"Yes")-_xlfn.MINIFS($J$5:$J$60,$A$5:$A$60,$A6,$H$5:$H$60,"Yes")))) | R6: =IF($H6<>"Yes","",IFERROR(ROUND(100*(IF($N6="",0,Weights!$B$5*$N6)+IF($O6="",0,Weights!$B$6*$O6)+IF($P6="",0,Weights!$B$7*$P6)+IF($Q6="",0,Weights!$B$8*$Q6))/(IF($N6="",0,Weights!$B$5)+IF($O6="",0,Weights!$B$6)+IF($P6="",0,Weights!$B$7)+IF($Q6="",0,Weights!$B$8)),2),"")) -> 45.2 | S6: =IF($R6="","",COUNTIFS($A$5:$A$60,$A6,$R$5:$R$60,">"&$R6)+1) -> 3 | T6: =IF(OR($H6<>"Yes",$E6=""),"",COUNTIFS($A$5:$A$60,$A6,$H$5:$H$60,"Yes",$E$5:$E$60,"<"&$E6)+1) -> 3 | U6: =IF($S6="","",$A6&"|"&$S6) -> 1|3 | V6: =IF($T6="","",$A6&"|"&$T6) -> 1|3 | W6: =IF($B6="","",$B6&"|"&$D6) -> Wireless Bluetooth Neckband Earphones|Flipkart
A7: 1 | B7: Wireless Bluetooth Neckband Earphones | C7: Audio | D7: Meesho | E7: 222 | F7: No Warranty | G7: 3.9 | H7: Yes | I7: 46310 | K7: Open | L7: Image | M7: =IF($F7="","",IF(ISNUMBER(SEARCH("no warranty",$F7)),0,IF(ISNUMBER(SEARCH("year",$F7)),12*VALUE(LEFT($F7,FIND(" ",$F7)-1)),IF(ISNUMBER(SEARCH("month",$F7)),VALUE(LEFT($F7,FIND(" ",$F7)-1)),"")))) -> 0 | N7: =IF(OR($H7<>"Yes",$E7=""),"",IF(_xlfn.MAXIFS($E$5:$E$60,$A$5:$A$60,$A7,$H$5:$H$60,"Yes")=_xlfn.MINIFS($E$5:$E$60,$A$5:$A$60,$A7,$H$5:$H$60,"Yes"),1,(_xlfn.MAXIFS($E$5:$E$60,$A$5:$A$60,$A7,$H$5:$H$60,"Yes")-$E7)/(_xlfn.MAXIFS($E$5:$E$60,$A$5:$A$60,$A7,$H$5:$H$60,"Yes")-_xlfn.MINIFS($E$5:$E$60,$A$5:$A$60,$A7,$H$5:$H$60,"Yes")))) -> 1 | O7: =IF(OR($H7<>"Yes",$G7=""),"",IF(Weights!$B$10="Relative",IF(_xlfn.MAXIFS($G$5:$G$60,$A$5:$A$60,$A7,$H$5:$H$60,"Yes")=_xlfn.MINIFS($G$5:$G$60,$A$5:$A$60,$A7,$H$5:$H$60,"Yes"),1,($G7-_xlfn.MINIFS($G$5:$G$60,$A$5:$A$60,$A7,$H$5:$H$60,"Yes"))/(_xlfn.MAXIFS($G$5:$G$60,$A$5:$A$60,$A7,$H$5:$H$60,"Yes")-_xlfn.MINIFS($G$5:$G$60,$A$5:$A$60,$A7,$H$5:$H$60,"Yes"))),$G7/5)) -> 0.78 | P7: =IF(OR($H7<>"Yes",$M7=""),"",IF(_xlfn.MAXIFS($M$5:$M$60,$A$5:$A$60,$A7,$H$5:$H$60,"Yes")=_xlfn.MINIFS($M$5:$M$60,$A$5:$A$60,$A7,$H$5:$H$60,"Yes"),1,($M7-_xlfn.MINIFS($M$5:$M$60,$A$5:$A$60,$A7,$H$5:$H$60,"Yes"))/(_xlfn.MAXIFS($M$5:$M$60,$A$5:$A$60,$A7,$H$5:$H$60,"Yes")-_xlfn.MINIFS($M$5:$M$60,$A$5:$A$60,$A7,$H$5:$H$60,"Yes")))) -> 0 | Q7: =IF(OR($H7<>"Yes",$J7=""),"",IF(_xlfn.MAXIFS($J$5:$J$60,$A$5:$A$60,$A7,$H$5:$H$60,"Yes")=_xlfn.MINIFS($J$5:$J$60,$A$5:$A$60,$A7,$H$5:$H$60,"Yes"),1,(_xlfn.MAXIFS($J$5:$J$60,$A$5:$A$60,$A7,$H$5:$H$60,"Yes")-$J7)/(_xlfn.MAXIFS($J$5:$J$60,$A$5:$A$60,$A7,$H$5:$H$60,"Yes")-_xlfn.MINIFS($J$5:$J$60,$A$5:$A$60,$A7,$H$5:$H$60,"Yes")))) | R7: =IF($H7<>"Yes","",IFERROR(ROUND(100*(IF($N7="",0,Weights!$B$5*$N7)+IF($O7="",0,Weights!$B$6*$O7)+IF($P7="",0,Weights!$B$7*$P7)+IF($Q7="",0,Weights!$B$8*$Q7))/(IF($N7="",0,Weights!$B$5)+IF($O7="",0,Weights!$B$6)+IF($P7="",0,Weights!$B$7)+IF($Q7="",0,Weights!$B$8)),2),"")) -> 73.4 | S7: =IF($R7="","",COUNTIFS($A$5:$A$60,$A7,$R$5:$R$60,">"&$R7)+1) -> 2 | T7: =IF(OR($H7<>"Yes",$E7=""),"",COUNTIFS($A$5:$A$60,$A7,$H$5:$H$60,"Yes",$E$5:$E$60,"<"&$E7)+1) -> 1 | U7: =IF($S7="","",$A7&"|"&$S7) -> 1|2 | V7: =IF($T7="","",$A7&"|"&$T7) -> 1|1 | W7: =IF($B7="","",$B7&"|"&$D7) -> Wireless Bluetooth Neckband Earphones|Meesho
A8: 2 | B8: True Wireless Earbuds with Charging Case | C8: Audio | D8: Amazon | E8: 999 | F8: 1 Year | G8: 3.8 | H8: Yes | I8: 46310 | K8: Open | L8: Image | M8: =IF($F8="","",IF(ISNUMBER(SEARCH("no warranty",$F8)),0,IF(ISNUMBER(SEARCH("year",$F8)),12*VALUE(LEFT($F8,FIND(" ",$F8)-1)),IF(ISNUMBER(SEARCH("month",$F8)),VALUE(LEFT($F8,FIND(" ",$F8)-1)),"")))) -> 12 | N8: =IF(OR($H8<>"Yes",$E8=""),"",IF(_xlfn.MAXIFS($E$5:$E$60,$A$5:$A$60,$A8,$H$5:$H$60,"Yes")=_xlfn.MINIFS($E$5:$E$60,$A$5:$A$60,$A8,$H$5:$H$60,"Yes"),1,(_xlfn.MAXIFS($E$5:$E$60,$A$5:$A$60,$A8,$H$5:$H$60,"Yes")-$E8)/(_xlfn.MAXIFS($E$5:$E$60,$A$5:$A$60,$A8,$H$5:$H$60,"Yes")-_xlfn.MINIFS($E$5:$E$60,$A$5:$A$60,$A8,$H$5:$H$60,"Yes")))) -> 0 | O8: =IF(OR($H8<>"Yes",$G8=""),"",IF(Weights!$B$10="Relative",IF(_xlfn.MAXIFS($G$5:$G$60,$A$5:$A$60,$A8,$H$5:$H$60,"Yes")=_xlfn.MINIFS($G$5:$G$60,$A$5:$A$60,$A8,$H$5:$H$60,"Yes"),1,($G8-_xlfn.MINIFS($G$5:$G$60,$A$5:$A$60,$A8,$H$5:$H$60,"Yes"))/(_xlfn.MAXIFS($G$5:$G$60,$A$5:$A$60,$A8,$H$5:$H$60,"Yes")-_xlfn.MINIFS($G$5:$G$60,$A$5:$A$60,$A8,$H$5:$H$60,"Yes"))),$G8/5)) -> 0.76 | P8: =IF(OR($H8<>"Yes",$M8=""),"",IF(_xlfn.MAXIFS($M$5:$M$60,$A$5:$A$60,$A8,$H$5:$H$60,"Yes")=_xlfn.MINIFS($M$5:$M$60,$A$5:$A$60,$A8,$H$5:$H$60,"Yes"),1,($M8-_xlfn.MINIFS($M$5:$M$60,$A$5:$A$60,$A8,$H$5:$H$60,"Yes"))/(_xlfn.MAXIFS($M$5:$M$60,$A$5:$A$60,$A8,$H$5:$H$60,"Yes")-_xlfn.MINIFS($M$5:$M$60,$A$5:$A$60,$A8,$H$5:$H$60,"Yes")))) -> 1 | Q8: =IF(OR($H8<>"Yes",$J8=""),"",IF(_xlfn.MAXIFS($J$5:$J$60,$A$5:$A$60,$A8,$H$5:$H$60,"Yes")=_xlfn.MINIFS($J$5:$J$60,$A$5:$A$60,$A8,$H$5:$H$60,"Yes"),1,(_xlfn.MAXIFS($J$5:$J$60,$A$5:$A$60,$A8,$H$5:$H$60,"Yes")-$J8)/(_xlfn.MAXIFS($J$5:$J$60,$A$5:$A$60,$A8,$H$5:$H$60,"Yes")-_xlfn.MINIFS($J$5:$J$60,$A$5:$A$60,$A8,$H$5:$H$60,"Yes")))) | R8: =IF($H8<>"Yes","",IFERROR(ROUND(100*(IF($N8="",0,Weights!$B$5*$N8)+IF($O8="",0,Weights!$B$6*$O8)+IF($P8="",0,Weights!$B$7*$P8)+IF($Q8="",0,Weights!$B$8*$Q8))/(IF($N8="",0,Weights!$B$5)+IF($O8="",0,Weights!$B$6)+IF($P8="",0,Weights!$B$7)+IF($Q8="",0,Weights!$B$8)),2),"")) -> 42.8 | S8: =IF($R8="","",COUNTIFS($A$5:$A$60,$A8,$R$5:$R$60,">"&$R8)+1) -> 3 | T8: =IF(OR($H8<>"Yes",$E8=""),"",COUNTIFS($A$5:$A$60,$A8,$H$5:$H$60,"Yes",$E$5:$E$60,"<"&$E8)+1) -> 3 | U8: =IF($S8="","",$A8&"|"&$S8) -> 2|3 | V8: =IF($T8="","",$A8&"|"&$T8) -> 2|3 | W8: =IF($B8="","",$B8&"|"&$D8) -> True Wireless Earbuds with Charging Case|Amazon
A9: 2 | B9: True Wireless Earbuds with Charging Case | C9: Audio | D9: Flipkart | E9: 899 | F9: 1 Year | G9: 4.1 | H9: Yes | I9: 46310 | K9: Open | L9: Image | M9: =IF($F9="","",IF(ISNUMBER(SEARCH("no warranty",$F9)),0,IF(ISNUMBER(SEARCH("year",$F9)),12*VALUE(LEFT($F9,FIND(" ",$F9)-1)),IF(ISNUMBER(SEARCH("month",$F9)),VALUE(LEFT($F9,FIND(" ",$F9)-1)),"")))) -> 12 | N9: =IF(OR($H9<>"Yes",$E9=""),"",IF(_xlfn.MAXIFS($E$5:$E$60,$A$5:$A$60,$A9,$H$5:$H$60,"Yes")=_xlfn.MINIFS($E$5:$E$60,$A$5:$A$60,$A9,$H$5:$H$60,"Yes"),1,(_xlfn.MAXIFS($E$5:$E$60,$A$5:$A$60,$A9,$H$5:$H$60,"Yes")-$E9)/(_xlfn.MAXIFS($E$5:$E$60,$A$5:$A$60,$A9,$H$5:$H$60,"Yes")-_xlfn.MINIFS($E$5:$E$60,$A$5:$A$60,$A9,$H$5:$H$60,"Yes")))) -> 0.23923445 | O9: =IF(OR($H9<>"Yes",$G9=""),"",IF(Weights!$B$10="Relative",IF(_xlfn.MAXIFS($G$5:$G$60,$A$5:$A$60,$A9,$H$5:$H$60,"Yes")=_xlfn.MINIFS($G$5:$G$60,$A$5:$A$60,$A9,$H$5:$H$60,"Yes"),1,($G9-_xlfn.MINIFS($G$5:$G$60,$A$5:$A$60,$A9,$H$5:$H$60,"Yes"))/(_xlfn.MAXIFS($G$5:$G$60,$A$5:$A$60,$A9,$H$5:$H$60,"Yes")-_xlfn.MINIFS($G$5:$G$60,$A$5:$A$60,$A9,$H$5:$H$60,"Yes"))),$G9/5)) -> 0.82 | P9: =IF(OR($H9<>"Yes",$M9=""),"",IF(_xlfn.MAXIFS($M$5:$M$60,$A$5:$A$60,$A9,$H$5:$H$60,"Yes")=_xlfn.MINIFS($M$5:$M$60,$A$5:$A$60,$A9,$H$5:$H$60,"Yes"),1,($M9-_xlfn.MINIFS($M$5:$M$60,$A$5:$A$60,$A9,$H$5:$H$60,"Yes"))/(_xlfn.MAXIFS($M$5:$M$60,$A$5:$A$60,$A9,$H$5:$H$60,"Yes")-_xlfn.MINIFS($M$5:$M$60,$A$5:$A$60,$A9,$H$5:$H$60,"Yes")))) -> 1 | Q9: =IF(OR($H9<>"Yes",$J9=""),"",IF(_xlfn.MAXIFS($J$5:$J$60,$A$5:$A$60,$A9,$H$5:$H$60,"Yes")=_xlfn.MINIFS($J$5:$J$60,$A$5:$A$60,$A9,$H$5:$H$60,"Yes"),1,(_xlfn.MAXIFS($J$5:$J$60,$A$5:$A$60,$A9,$H$5:$H$60,"Yes")-$J9)/(_xlfn.MAXIFS($J$5:$J$60,$A$5:$A$60,$A9,$H$5:$H$60,"Yes")-_xlfn.MINIFS($J$5:$J$60,$A$5:$A$60,$A9,$H$5:$H$60,"Yes")))) | R9: =IF($H9<>"Yes","",IFERROR(ROUND(100*(IF($N9="",0,Weights!$B$5*$N9)+IF($O9="",0,Weights!$B$6*$O9)+IF($P9="",0,Weights!$B$7*$P9)+IF($Q9="",0,Weights!$B$8*$Q9))/(IF($N9="",0,Weights!$B$5)+IF($O9="",0,Weights!$B$6)+IF($P9="",0,Weights!$B$7)+IF($Q9="",0,Weights!$B$8)),2),"")) -> 56.56 | S9: =IF($R9="","",COUNTIFS($A$5:$A$60,$A9,$R$5:$R$60,">"&$R9)+1) -> 2 | T9: =IF(OR($H9<>"Yes",$E9=""),"",COUNTIFS($A$5:$A$60,$A9,$H$5:$H$60,"Yes",$E$5:$E$60,"<"&$E9)+1) -> 2 | U9: =IF($S9="","",$A9&"|"&$S9) -> 2|2 | V9: =IF($T9="","",$A9&"|"&$T9) -> 2|2 | W9: =IF($B9="","",$B9&"|"&$D9) -> True Wireless Earbuds with Charging Case|Flipkart
A10: 2 | B10: True Wireless Earbuds with Charging Case | C10: Audio | D10: Meesho | E10: 581 | F10: 1 Month | G10: 4.1 | H10: Yes | I10: 46310 | K10: Open | L10: Image | M10: =IF($F10="","",IF(ISNUMBER(SEARCH("no warranty",$F10)),0,IF(ISNUMBER(SEARCH("year",$F10)),12*VALUE(LEFT($F10,FIND(" ",$F10)-1)),IF(ISNUMBER(SEARCH("month",$F10)),VALUE(LEFT($F10,FIND(" ",$F10)-1)),"")))) -> 1 | N10: =IF(OR($H10<>"Yes",$E10=""),"",IF(_xlfn.MAXIFS($E$5:$E$60,$A$5:$A$60,$A10,$H$5:$H$60,"Yes")=_xlfn.MINIFS($E$5:$E$60,$A$5:$A$60,$A10,$H$5:$H$60,"Yes"),1,(_xlfn.MAXIFS($E$5:$E$60,$A$5:$A$60,$A10,$H$5:$H$60,"Yes")-$E10)/(_xlfn.MAXIFS($E$5:$E$60,$A$5:$A$60,$A10,$H$5:$H$60,"Yes")-_xlfn.MINIFS($E$5:$E$60,$A$5:$A$60,$A10,$H$5:$H$60,"Yes")))) -> 1 | O10: =IF(OR($H10<>"Yes",$G10=""),"",IF(Weights!$B$10="Relative",IF(_xlfn.MAXIFS($G$5:$G$60,$A$5:$A$60,$A10,$H$5:$H$60,"Yes")=_xlfn.MINIFS($G$5:$G$60,$A$5:$A$60,$A10,$H$5:$H$60,"Yes"),1,($G10-_xlfn.MINIFS($G$5:$G$60,$A$5:$A$60,$A10,$H$5:$H$60,"Yes"))/(_xlfn.MAXIFS($G$5:$G$60,$A$5:$A$60,$A10,$H$5:$H$60,"Yes")-_xlfn.MINIFS($G$5:$G$60,$A$5:$A$60,$A10,$H$5:$H$60,"Yes"))),$G10/5)) -> 0.82 | P10: =IF(OR($H10<>"Yes",$M10=""),"",IF(_xlfn.MAXIFS($M$5:$M$60,$A$5:$A$60,$A10,$H$5:$H$60,"Yes")=_xlfn.MINIFS($M$5:$M$60,$A$5:$A$60,$A10,$H$5:$H$60,"Yes"),1,($M10-_xlfn.MINIFS($M$5:$M$60,$A$5:$A$60,$A10,$H$5:$H$60,"Yes"))/(_xlfn.MAXIFS($M$5:$M$60,$A$5:$A$60,$A10,$H$5:$H$60,"Yes")-_xlfn.MINIFS($M$5:$M$60,$A$5:$A$60,$A10,$H$5:$H$60,"Yes")))) -> 0 | Q10: =IF(OR($H10<>"Yes",$J10=""),"",IF(_xlfn.MAXIFS($J$5:$J$60,$A$5:$A$60,$A10,$H$5:$H$60,"Yes")=_xlfn.MINIFS($J$5:$J$60,$A$5:$A$60,$A10,$H$5:$H$60,"Yes"),1,(_xlfn.MAXIFS($J$5:$J$60,$A$5:$A$60,$A10,$H$5:$H$60,"Yes")-$J10)/(_xlfn.MAXIFS($J$5:$J$60,$A$5:$A$60,$A10,$H$5:$H$60,"Yes")-_xlfn.MINIFS($J$5:$J$60,$A$5:$A$60,$A10,$H$5:$H$60,"Yes")))) | R10: =IF($H10<>"Yes","",IFERROR(ROUND(100*(IF($N10="",0,Weights!$B$5*$N10)+IF($O10="",0,Weights!$B$6*$O10)+IF($P10="",0,Weights!$B$7*$P10)+IF($Q10="",0,Weights!$B$8*$Q10))/(IF($N10="",0,Weights!$B$5)+IF($O10="",0,Weights!$B$6)+IF($P10="",0,Weights!$B$7)+IF($Q10="",0,Weights!$B$8)),2),"")) -> 74.6 | S10: =IF($R10="","",COUNTIFS($A$5:$A$60,$A10,$R$5:$R$60,">"&$R10)+1) -> 1 | T10: =IF(OR($H10<>"Yes",$E10=""),"",COUNTIFS($A$5:$A$60,$A10,$H$5:$H$60,"Yes",$E$5:$E$60,"<"&$E10)+1) -> 1 | U10: =IF($S10="","",$A10&"|"&$S10) -> 2|1 | V10: =IF($T10="","",$A10&"|"&$T10) -> 2|1 | W10: =IF($B10="","",$B10&"|"&$D10) -> True Wireless Earbuds with Charging Case|Meesho
A11: 3 | B11: Wired In-Ear Earphones with Mic | C11: Audio | D11: Amazon | E11: 94 | F11: 1 year | G11: 3.3 | H11: Yes | I11: 46310 | K11: Open | L11: Image | M11: =IF($F11="","",IF(ISNUMBER(SEARCH("no warranty",$F11)),0,IF(ISNUMBER(SEARCH("year",$F11)),12*VALUE(LEFT($F11,FIND(" ",$F11)-1)),IF(ISNUMBER(SEARCH("month",$F11)),VALUE(LEFT($F11,FIND(" ",$F11)-1)),"")))) -> 12 | N11: =IF(OR($H11<>"Yes",$E11=""),"",IF(_xlfn.MAXIFS($E$5:$E$60,$A$5:$A$60,$A11,$H$5:$H$60,"Yes")=_xlfn.MINIFS($E$5:$E$60,$A$5:$A$60,$A11,$H$5:$H$60,"Yes"),1,(_xlfn.MAXIFS($E$5:$E$60,$A$5:$A$60,$A11,$H$5:$H$60,"Yes")-$E11)/(_xlfn.MAXIFS($E$5:$E$60,$A$5:$A$60,$A11,$H$5:$H$60,"Yes")-_xlfn.MINIFS($E$5:$E$60,$A$5:$A$60,$A11,$H$5:$H$60,"Yes")))) -> 1 | O11: =IF(OR($H11<>"Yes",$G11=""),"",IF(Weights!$B$10="Relative",IF(_xlfn.MAXIFS($G$5:$G$60,$A$5:$A$60,$A11,$H$5:$H$60,"Yes")=_xlfn.MINIFS($G$5:$G$60,$A$5:$A$60,$A11,$H$5:$H$60,"Yes"),1,($G11-_xlfn.MINIFS($G$5:$G$60,$A$5:$A$60,$A11,$H$5:$H$60,"Yes"))/(_xlfn.MAXIFS($G$5:$G$60,$A$5:$A$60,$A11,$H$5:$H$60,"Yes")-_xlfn.MINIFS($G$5:$G$60,$A$5:$A$60,$A11,$H$5:$H$60,"Yes"))),$G11/5)) -> 0.66 | P11: =IF(OR($H11<>"Yes",$M11=""),"",IF(_xlfn.MAXIFS($M$5:$M$60,$A$5:$A$60,$A11,$H$5:$H$60,"Yes")=_xlfn.MINIFS($M$5:$M$60,$A$5:$A$60,$A11,$H$5:$H$60,"Yes"),1,($M11-_xlfn.MINIFS($M$5:$M$60,$A$5:$A$60,$A11,$H$5:$H$60,"Yes"))/(_xlfn.MAXIFS($M$5:$M$60,$A$5:$A$60,$A11,$H$5:$H$60,"Yes")-_xlfn.MINIFS($M$5:$M$60,$A$5:$A$60,$A11,$H$5:$H$60,"Yes")))) -> 1 | Q11: =IF(OR($H11<>"Yes",$J11=""),"",IF(_xlfn.MAXIFS($J$5:$J$60,$A$5:$A$60,$A11,$H$5:$H$60,"Yes")=_xlfn.MINIFS($J$5:$J$60,$A$5:$A$60,$A11,$H$5:$H$60,"Yes"),1,(_xlfn.MAXIFS($J$5:$J$60,$A$5:$A$60,$A11,$H$5:$H$60,"Yes")-$J11)/(_xlfn.MAXIFS($J$5:$J$60,$A$5:$A$60,$A11,$H$5:$H$60,"Yes")-_xlfn.MINIFS($J$5:$J$60,$A$5:$A$60,$A11,$H$5:$H$60,"Yes")))) | R11: =IF($H11<>"Yes","",IFERROR(ROUND(100*(IF($N11="",0,Weights!$B$5*$N11)+IF($O11="",0,Weights!$B$6*$O11)+IF($P11="",0,Weights!$B$7*$P11)+IF($Q11="",0,Weights!$B$8*$Q11))/(IF($N11="",0,Weights!$B$5)+IF($O11="",0,Weights!$B$6)+IF($P11="",0,Weights!$B$7)+IF($Q11="",0,Weights!$B$8)),2),"")) -> 89.8 | S11: =IF($R11="","",COUNTIFS($A$5:$A$60,$A11,$R$5:$R$60,">"&$R11)+1) -> 1 | T11: =IF(OR($H11<>"Yes",$E11=""),"",COUNTIFS($A$5:$A$60,$A11,$H$5:$H$60,"Yes",$E$5:$E$60,"<"&$E11)+1) -> 1 | U11: =IF($S11="","",$A11&"|"&$S11) -> 3|1 | V11: =IF($T11="","",$A11&"|"&$T11) -> 3|1 | W11: =IF($B11="","",$B11&"|"&$D11) -> Wired In-Ear Earphones with Mic|Amazon
A12: 3 | B12: Wired In-Ear Earphones with Mic | C12: Audio | D12: Flipkart | E12: 399 | F12: 1 year | G12: 4.2 | H12: Yes | I12: 46310 | K12: Open | L12: Image | M12: =IF($F12="","",IF(ISNUMBER(SEARCH("no warranty",$F12)),0,IF(ISNUMBER(SEARCH("year",$F12)),12*VALUE(LEFT($F12,FIND(" ",$F12)-1)),IF(ISNUMBER(SEARCH("month",$F12)),VALUE(LEFT($F12,FIND(" ",$F12)-1)),"")))) -> 12 | N12: =IF(OR($H12<>"Yes",$E12=""),"",IF(_xlfn.MAXIFS($E$5:$E$60,$A$5:$A$60,$A12,$H$5:$H$60,"Yes")=_xlfn.MINIFS($E$5:$E$60,$A$5:$A$60,$A12,$H$5:$H$60,"Yes"),1,(_xlfn.MAXIFS($E$5:$E$60,$A$5:$A$60,$A12,$H$5:$H$60,"Yes")-$E12)/(_xlfn.MAXIFS($E$5:$E$60,$A$5:$A$60,$A12,$H$5:$H$60,"Yes")-_xlfn.MINIFS($E$5:$E$60,$A$5:$A$60,$A12,$H$5:$H$60,"Yes")))) -> 0 | O12: =IF(OR($H12<>"Yes",$G12=""),"",IF(Weights!$B$10="Relative",IF(_xlfn.MAXIFS($G$5:$G$60,$A$5:$A$60,$A12,$H$5:$H$60,"Yes")=_xlfn.MINIFS($G$5:$G$60,$A$5:$A$60,$A12,$H$5:$H$60,"Yes"),1,($G12-_xlfn.MINIFS($G$5:$G$60,$A$5:$A$60,$A12,$H$5:$H$60,"Yes"))/(_xlfn.MAXIFS($G$5:$G$60,$A$5:$A$60,$A12,$H$5:$H$60,"Yes")-_xlfn.MINIFS($G$5:$G$60,$A$5:$A$60,$A12,$H$5:$H$60,"Yes"))),$G12/5)) -> 0.84 | P12: =IF(OR($H12<>"Yes",$M12=""),"",IF(_xlfn.MAXIFS($M$5:$M$60,$A$5:$A$60,$A12,$H$5:$H$60,"Yes")=_xlfn.MINIFS($M$5:$M$60,$A$5:$A$60,$A12,$H$5:$H$60,"Yes"),1,($M12-_xlfn.MINIFS($M$5:$M$60,$A$5:$A$60,$A12,$H$5:$H$60,"Yes"))/(_xlfn.MAXIFS($M$5:$M$60,$A$5:$A$60,$A12,$H$5:$H$60,"Yes")-_xlfn.MINIFS($M$5:$M$60,$A$5:$A$60,$A12,$H$5:$H$60,"Yes")))) -> 1 | Q12: =IF(OR($H12<>"Yes",$J12=""),"",IF(_xlfn.MAXIFS($J$5:$J$60,$A$5:$A$60,$A12,$H$5:$H$60,"Yes")=_xlfn.MINIFS($J$5:$J$60,$A$5:$A$60,$A12,$H$5:$H$60,"Yes"),1,(_xlfn.MAXIFS($J$5:$J$60,$A$5:$A$60,$A12,$H$5:$H$60,"Yes")-$J12)/(_xlfn.MAXIFS($J$5:$J$60,$A$5:$A$60,$A12,$H$5:$H$60,"Yes")-_xlfn.MINIFS($J$5:$J$60,$A$5:$A$60,$A12,$H$5:$H$60,"Yes")))) | R12: =IF($H12<>"Yes","",IFERROR(ROUND(100*(IF($N12="",0,Weights!$B$5*$N12)+IF($O12="",0,Weights!$B$6*$O12)+IF($P12="",0,Weights!$B$7*$P12)+IF($Q12="",0,Weights!$B$8*$Q12))/(IF($N12="",0,Weights!$B$5)+IF($O12="",0,Weights!$B$6)+IF($P12="",0,Weights!$B$7)+IF($Q12="",0,Weights!$B$8)),2),"")) -> 45.2 | S12: =IF($R12="","",COUNTIFS($A$5:$A$60,$A12,$R$5:$R$60,">"&$R12)+1) -> 3 | T12: =IF(OR($H12<>"Yes",$E12=""),"",COUNTIFS($A$5:$A$60,$A12,$H$5:$H$60,"Yes",$E$5:$E$60,"<"&$E12)+1) -> 3 | U12: =IF($S12="","",$A12&"|"&$S12) -> 3|3 | V12: =IF($T12="","",$A12&"|"&$T12) -> 3|3 | W12: =IF($B12="","",$B12&"|"&$D12) -> Wired In-Ear Earphones with Mic|Flipkart
A13: 3 | B13: Wired In-Ear Earphones with Mic | C13: Audio | D13: Meesho | E13: 123 | F13: 1 Month | G13: 3.8 | H13: Yes | I13: 46310 | K13: Open | L13: Image | M13: =IF($F13="","",IF(ISNUMBER(SEARCH("no warranty",$F13)),0,IF(ISNUMBER(SEARCH("year",$F13)),12*VALUE(LEFT($F13,FIND(" ",$F13)-1)),IF(ISNUMBER(SEARCH("month",$F13)),VALUE(LEFT($F13,FIND(" ",$F13)-1)),"")))) -> 1 | N13: =IF(OR($H13<>"Yes",$E13=""),"",IF(_xlfn.MAXIFS($E$5:$E$60,$A$5:$A$60,$A13,$H$5:$H$60,"Yes")=_xlfn.MINIFS($E$5:$E$60,$A$5:$A$60,$A13,$H$5:$H$60,"Yes"),1,(_xlfn.MAXIFS($E$5:$E$60,$A$5:$A$60,$A13,$H$5:$H$60,"Yes")-$E13)/(_xlfn.MAXIFS($E$5:$E$60,$A$5:$A$60,$A13,$H$5:$H$60,"Yes")-_xlfn.MINIFS($E$5:$E$60,$A$5:$A$60,$A13,$H$5:$H$60,"Yes")))) -> 0.90491803 | O13: =IF(OR($H13<>"Yes",$G13=""),"",IF(Weights!$B$10="Relative",IF(_xlfn.MAXIFS($G$5:$G$60,$A$5:$A$60,$A13,$H$5:$H$60,"Yes")=_xlfn.MINIFS($G$5:$G$60,$A$5:$A$60,$A13,$H$5:$H$60,"Yes"),1,($G13-_xlfn.MINIFS($G$5:$G$60,$A$5:$A$60,$A13,$H$5:$H$60,"Yes"))/(_xlfn.MAXIFS($G$5:$G$60,$A$5:$A$60,$A13,$H$5:$H$60,"Yes")-_xlfn.MINIFS($G$5:$G$60,$A$5:$A$60,$A13,$H$5:$H$60,"Yes"))),$G13/5)) -> 0.76 | P13: =IF(OR($H13<>"Yes",$M13=""),"",IF(_xlfn.MAXIFS($M$5:$M$60,$A$5:$A$60,$A13,$H$5:$H$60,"Yes")=_xlfn.MINIFS($M$5:$M$60,$A$5:$A$60,$A13,$H$5:$H$60,"Yes"),1,($M13-_xlfn.MINIFS($M$5:$M$60,$A$5:$A$60,$A13,$H$5:$H$60,"Yes"))/(_xlfn.MAXIFS($M$5:$M$60,$A$5:$A$60,$A13,$H$5:$H$60,"Yes")-_xlfn.MINIFS($M$5:$M$60,$A$5:$A$60,$A13,$H$5:$H$60,"Yes")))) -> 0 | Q13: =IF(OR($H13<>"Yes",$J13=""),"",IF(_xlfn.MAXIFS($J$5:$J$60,$A$5:$A$60,$A13,$H$5:$H$60,"Yes")=_xlfn.MINIFS($J$5:$J$60,$A$5:$A$60,$A13,$H$5:$H$60,"Yes"),1,(_xlfn.MAXIFS($J$5:$J$60,$A$5:$A$60,$A13,$H$5:$H$60,"Yes")-$J13)/(_xlfn.MAXIFS($J$5:$J$60,$A$5:$A$60,$A13,$H$5:$H$60,"Yes")-_xlfn.MINIFS($J$5:$J$60,$A$5:$A$60,$A13,$H$5:$H$60,"Yes")))) | R13: =IF($H13<>"Yes","",IFERROR(ROUND(100*(IF($N13="",0,Weights!$B$5*$N13)+IF($O13="",0,Weights!$B$6*$O13)+IF($P13="",0,Weights!$B$7*$P13)+IF($Q13="",0,Weights!$B$8*$Q13))/(IF($N13="",0,Weights!$B$5)+IF($O13="",0,Weights!$B$6)+IF($P13="",0,Weights!$B$7)+IF($Q13="",0,Weights!$B$8)),2),"")) -> 68.05 | S13: =IF($R13="","",COUNTIFS($A$5:$A$60,$A13,$R$5:$R$60,">"&$R13)+1) -> 2 | T13: =IF(OR($H13<>"Yes",$E13=""),"",COUNTIFS($A$5:$A$60,$A13,$H$5:$H$60,"Yes",$E$5:$E$60,"<"&$E13)+1) -> 2 | U13: =IF($S13="","",$A13&"|"&$S13) -> 3|2 | V13: =IF($T13="","",$A13&"|"&$T13) -> 3|2 | W13: =IF($B13="","",$B13&"|"&$D13) -> Wired In-Ear Earphones with Mic|Meesho
A14: 4 | B14: Women's Cotton Churidar Set | C14: Clothing | D14: Amazon | E14: 853 | F14: No Warranty | G14: 4.2 | H14: Yes | I14: 46310 | K14: Open | L14: Image | M14: =IF($F14="","",IF(ISNUMBER(SEARCH("no warranty",$F14)),0,IF(ISNUMBER(SEARCH("year",$F14)),12*VALUE(LEFT($F14,FIND(" ",$F14)-1)),IF(ISNUMBER(SEARCH("month",$F14)),VALUE(LEFT($F14,FIND(" ",$F14)-1)),"")))) -> 0 | N14: =IF(OR($H14<>"Yes",$E14=""),"",IF(_xlfn.MAXIFS($E$5:$E$60,$A$5:$A$60,$A14,$H$5:$H$60,"Yes")=_xlfn.MINIFS($E$5:$E$60,$A$5:$A$60,$A14,$H$5:$H$60,"Yes"),1,(_xlfn.MAXIFS($E$5:$E$60,$A$5:$A$60,$A14,$H$5:$H$60,"Yes")-$E14)/(_xlfn.MAXIFS($E$5:$E$60,$A$5:$A$60,$A14,$H$5:$H$60,"Yes")-_xlfn.MINIFS($E$5:$E$60,$A$5:$A$60,$A14,$H$5:$H$60,"Yes")))) -> 0 | O14: =IF(OR($H14<>"Yes",$G14=""),"",IF(Weights!$B$10="Relative",IF(_xlfn.MAXIFS($G$5:$G$60,$A$5:$A$60,$A14,$H$5:$H$60,"Yes")=_xlfn.MINIFS($G$5:$G$60,$A$5:$A$60,$A14,$H$5:$H$60,"Yes"),1,($G14-_xlfn.MINIFS($G$5:$G$60,$A$5:$A$60,$A14,$H$5:$H$60,"Yes"))/(_xlfn.MAXIFS($G$5:$G$60,$A$5:$A$60,$A14,$H$5:$H$60,"Yes")-_xlfn.MINIFS($G$5:$G$60,$A$5:$A$60,$A14,$H$5:$H$60,"Yes"))),$G14/5)) -> 0.84 | P14: =IF(OR($H14<>"Yes",$M14=""),"",IF(_xlfn.MAXIFS($M$5:$M$60,$A$5:$A$60,$A14,$H$5:$H$60,"Yes")=_xlfn.MINIFS($M$5:$M$60,$A$5:$A$60,$A14,$H$5:$H$60,"Yes"),1,($M14-_xlfn.MINIFS($M$5:$M$60,$A$5:$A$60,$A14,$H$5:$H$60,"Yes"))/(_xlfn.MAXIFS($M$5:$M$60,$A$5:$A$60,$A14,$H$5:$H$60,"Yes")-_xlfn.MINIFS($M$5:$M$60,$A$5:$A$60,$A14,$H$5:$H$60,"Yes")))) -> 1 | Q14: =IF(OR($H14<>"Yes",$J14=""),"",IF(_xlfn.MAXIFS($J$5:$J$60,$A$5:$A$60,$A14,$H$5:$H$60,"Yes")=_xlfn.MINIFS($J$5:$J$60,$A$5:$A$60,$A14,$H$5:$H$60,"Yes"),1,(_xlfn.MAXIFS($J$5:$J$60,$A$5:$A$60,$A14,$H$5:$H$60,"Yes")-$J14)/(_xlfn.MAXIFS($J$5:$J$60,$A$5:$A$60,$A14,$H$5:$H$60,"Yes")-_xlfn.MINIFS($J$5:$J$60,$A$5:$A$60,$A14,$H$5:$H$60,"Yes")))) | R14: =IF($H14<>"Yes","",IFERROR(ROUND(100*(IF($N14="",0,Weights!$B$5*$N14)+IF($O14="",0,Weights!$B$6*$O14)+IF($P14="",0,Weights!$B$7*$P14)+IF($Q14="",0,Weights!$B$8*$Q14))/(IF($N14="",0,Weights!$B$5)+IF($O14="",0,Weights!$B$6)+IF($P14="",0,Weights!$B$7)+IF($Q14="",0,Weights!$B$8)),2),"")) -> 45.2 | S14: =IF($R14="","",COUNTIFS($A$5:$A$60,$A14,$R$5:$R$60,">"&$R14)+1) -> 3 | T14: =IF(OR($H14<>"Yes",$E14=""),"",COUNTIFS($A$5:$A$60,$A14,$H$5:$H$60,"Yes",$E$5:$E$60,"<"&$E14)+1) -> 3 | U14: =IF($S14="","",$A14&"|"&$S14) -> 4|3 | V14: =IF($T14="","",$A14&"|"&$T14) -> 4|3 | W14: =IF($B14="","",$B14&"|"&$D14) -> Women's Cotton Churidar Set|Amazon
A15: 4 | B15: Women's Cotton Churidar Set | C15: Clothing | D15: Flipkart | E15: 410 | F15: No Warranty | G15: 4 | H15: Yes | I15: 46310 | K15: Open | M15: =IF($F15="","",IF(ISNUMBER(SEARCH("no warranty",$F15)),0,IF(ISNUMBER(SEARCH("year",$F15)),12*VALUE(LEFT($F15,FIND(" ",$F15)-1)),IF(ISNUMBER(SEARCH("month",$F15)),VALUE(LEFT($F15,FIND(" ",$F15)-1)),"")))) -> 0 | N15: =IF(OR($H15<>"Yes",$E15=""),"",IF(_xlfn.MAXIFS($E$5:$E$60,$A$5:$A$60,$A15,$H$5:$H$60,"Yes")=_xlfn.MINIFS($E$5:$E$60,$A$5:$A$60,$A15,$H$5:$H$60,"Yes"),1,(_xlfn.MAXIFS($E$5:$E$60,$A$5:$A$60,$A15,$H$5:$H$60,"Yes")-$E15)/(_xlfn.MAXIFS($E$5:$E$60,$A$5:$A$60,$A15,$H$5:$H$60,"Yes")-_xlfn.MINIFS($E$5:$E$60,$A$5:$A$60,$A15,$H$5:$H$60,"Yes")))) -> 0.92872117 | O15: =IF(OR($H15<>"Yes",$G15=""),"",IF(Weights!$B$10="Relative",IF(_xlfn.MAXIFS($G$5:$G$60,$A$5:$A$60,$A15,$H$5:$H$60,"Yes")=_xlfn.MINIFS($G$5:$G$60,$A$5:$A$60,$A15,$H$5:$H$60,"Yes"),1,($G15-_xlfn.MINIFS($G$5:$G$60,$A$5:$A$60,$A15,$H$5:$H$60,"Yes"))/(_xlfn.MAXIFS($G$5:$G$60,$A$5:$A$60,$A15,$H$5:$H$60,"Yes")-_xlfn.MINIFS($G$5:$G$60,$A$5:$A$60,$A15,$H$5:$H$60,"Yes"))),$G15/5)) -> 0.8 | P15: =IF(OR($H15<>"Yes",$M15=""),"",IF(_xlfn.MAXIFS($M$5:$M$60,$A$5:$A$60,$A15,$H$5:$H$60,"Yes")=_xlfn.MINIFS($M$5:$M$60,$A$5:$A$60,$A15,$H$5:$H$60,"Yes"),1,($M15-_xlfn.MINIFS($M$5:$M$60,$A$5:$A$60,$A15,$H$5:$H$60,"Yes"))/(_xlfn.MAXIFS($M$5:$M$60,$A$5:$A$60,$A15,$H$5:$H$60,"Yes")-_xlfn.MINIFS($M$5:$M$60,$A$5:$A$60,$A15,$H$5:$H$60,"Yes")))) -> 1 | Q15: =IF(OR($H15<>"Yes",$J15=""),"",IF(_xlfn.MAXIFS($J$5:$J$60,$A$5:$A$60,$A15,$H$5:$H$60,"Yes")=_xlfn.MINIFS($J$5:$J$60,$A$5:$A$60,$A15,$H$5:$H$60,"Yes"),1,(_xlfn.MAXIFS($J$5:$J$60,$A$5:$A$60,$A15,$H$5:$H$60,"Yes")-$J15)/(_xlfn.MAXIFS($J$5:$J$60,$A$5:$A$60,$A15,$H$5:$H$60,"Yes")-_xlfn.MINIFS($J$5:$J$60,$A$5:$A$60,$A15,$H$5:$H$60,"Yes")))) | R15: =IF($H15<>"Yes","",IFERROR(ROUND(100*(IF($N15="",0,Weights!$B$5*$N15)+IF($O15="",0,Weights!$B$6*$O15)+IF($P15="",0,Weights!$B$7*$P15)+IF($Q15="",0,Weights!$B$8*$Q15))/(IF($N15="",0,Weights!$B$5)+IF($O15="",0,Weights!$B$6)+IF($P15="",0,Weights!$B$7)+IF($Q15="",0,Weights!$B$8)),2),"")) -> 90.44 | S15: =IF($R15="","",COUNTIFS($A$5:$A$60,$A15,$R$5:$R$60,">"&$R15)+1) -> 2 | T15: =IF(OR($H15<>"Yes",$E15=""),"",COUNTIFS($A$5:$A$60,$A15,$H$5:$H$60,"Yes",$E$5:$E$60,"<"&$E15)+1) -> 2 | U15: =IF($S15="","",$A15&"|"&$S15) -> 4|2 | V15: =IF($T15="","",$A15&"|"&$T15) -> 4|2 | W15: =IF($B15="","",$B15&"|"&$D15) -> Women's Cotton Churidar Set|Flipkart
A16: 4 | B16: Women's Cotton Churidar Set | C16: Clothing | D16: Meesho | E16: 376 | F16: No Warranty | G16: 4.5 | H16: Yes | I16: 46310 | K16: Open | L16: Image | M16: =IF($F16="","",IF(ISNUMBER(SEARCH("no warranty",$F16)),0,IF(ISNUMBER(SEARCH("year",$F16)),12*VALUE(LEFT($F16,FIND(" ",$F16)-1)),IF(ISNUMBER(SEARCH("month",$F16)),VALUE(LEFT($F16,FIND(" ",$F16)-1)),"")))) -> 0 | N16: =IF(OR($H16<>"Yes",$E16=""),"",IF(_xlfn.MAXIFS($E$5:$E$60,$A$5:$A$60,$A16,$H$5:$H$60,"Yes")=_xlfn.MINIFS($E$5:$E$60,$A$5:$A$60,$A16,$H$5:$H$60,"Yes"),1,(_xlfn.MAXIFS($E$5:$E$60,$A$5:$A$60,$A16,$H$5:$H$60,"Yes")-$E16)/(_xlfn.MAXIFS($E$5:$E$60,$A$5:$A$60,$A16,$H$5:$H$60,"Yes")-_xlfn.MINIFS($E$5:$E$60,$A$5:$A$60,$A16,$H$5:$H$60,"Yes")))) -> 1 | O16: =IF(OR($H16<>"Yes",$G16=""),"",IF(Weights!$B$10="Relative",IF(_xlfn.MAXIFS($G$5:$G$60,$A$5:$A$60,$A16,$H$5:$H$60,"Yes")=_xlfn.MINIFS($G$5:$G$60,$A$5:$A$60,$A16,$H$5:$H$60,"Yes"),1,($G16-_xlfn.MINIFS($G$5:$G$60,$A$5:$A$60,$A16,$H$5:$H$60,"Yes"))/(_xlfn.MAXIFS($G$5:$G$60,$A$5:$A$60,$A16,$H$5:$H$60,"Yes")-_xlfn.MINIFS($G$5:$G$60,$A$5:$A$60,$A16,$H$5:$H$60,"Yes"))),$G16/5)) -> 0.9 | P16: =IF(OR($H16<>"Yes",$M16=""),"",IF(_xlfn.MAXIFS($M$5:$M$60,$A$5:$A$60,$A16,$H$5:$H$60,"Yes")=_xlfn.MINIFS($M$5:$M$60,$A$5:$A$60,$A16,$H$5:$H$60,"Yes"),1,($M16-_xlfn.MINIFS($M$5:$M$60,$A$5:$A$60,$A16,$H$5:$H$60,"Yes"))/(_xlfn.MAXIFS($M$5:$M$60,$A$5:$A$60,$A16,$H$5:$H$60,"Yes")-_xlfn.MINIFS($M$5:$M$60,$A$5:$A$60,$A16,$H$5:$H$60,"Yes")))) -> 1 | Q16: =IF(OR($H16<>"Yes",$J16=""),"",IF(_xlfn.MAXIFS($J$5:$J$60,$A$5:$A$60,$A16,$H$5:$H$60,"Yes")=_xlfn.MINIFS($J$5:$J$60,$A$5:$A$60,$A16,$H$5:$H$60,"Yes"),1,(_xlfn.MAXIFS($J$5:$J$60,$A$5:$A$60,$A16,$H$5:$H$60,"Yes")-$J16)/(_xlfn.MAXIFS($J$5:$J$60,$A$5:$A$60,$A16,$H$5:$H$60,"Yes")-_xlfn.MINIFS($J$5:$J$60,$A$5:$A$60,$A16,$H$5:$H$60,"Yes")))) | R16: =IF($H16<>"Yes","",IFERROR(ROUND(100*(IF($N16="",0,Weights!$B$5*$N16)+IF($O16="",0,Weights!$B$6*$O16)+IF($P16="",0,Weights!$B$7*$P16)+IF($Q16="",0,Weights!$B$8*$Q16))/(IF($N16="",0,Weights!$B$5)+IF($O16="",0,Weights!$B$6)+IF($P16="",0,Weights!$B$7)+IF($Q16="",0,Weights!$B$8)),2),"")) -> 97 | S16: =IF($R16="","",COUNTIFS($A$5:$A$60,$A16,$R$5:$R$60,">"&$R16)+1) -> 1 | T16: =IF(OR($H16<>"Yes",$E16=""),"",COUNTIFS($A$5:$A$60,$A16,$H$5:$H$60,"Yes",$E$5:$E$60,"<"&$E16)+1) -> 1 | U16: =IF($S16="","",$A16&"|"&$S16) -> 4|1 | V16: =IF($T16="","",$A16&"|"&$T16) -> 4|1 | W16: =IF($B16="","",$B16&"|"&$D16) -> Women's Cotton Churidar Set|Meesho
A17: 5 | B17: Girls Cotton Party Frock | C17: Clothing | D17: Amazon | E17: 659 | F17: No Warranty | G17: 3.6 | H17: Yes | I17: 46310 | K17: Open | L17: Image | M17: =IF($F17="","",IF(ISNUMBER(SEARCH("no warranty",$F17)),0,IF(ISNUMBER(SEARCH("year",$F17)),12*VALUE(LEFT($F17,FIND(" ",$F17)-1)),IF(ISNUMBER(SEARCH("month",$F17)),VALUE(LEFT($F17,FIND(" ",$F17)-1)),"")))) -> 0 | N17: =IF(OR($H17<>"Yes",$E17=""),"",IF(_xlfn.MAXIFS($E$5:$E$60,$A$5:$A$60,$A17,$H$5:$H$60,"Yes")=_xlfn.MINIFS($E$5:$E$60,$A$5:$A$60,$A17,$H$5:$H$60,"Yes"),1,(_xlfn.MAXIFS($E$5:$E$60,$A$5:$A$60,$A17,$H$5:$H$60,"Yes")-$E17)/(_xlfn.MAXIFS($E$5:$E$60,$A$5:$A$60,$A17,$H$5:$H$60,"Yes")-_xlfn.MINIFS($E$5:$E$60,$A$5:$A$60,$A17,$H$5:$H$60,"Yes")))) -> 0 | O17: =IF(OR($H17<>"Yes",$G17=""),"",IF(Weights!$B$10="Relative",IF(_xlfn.MAXIFS($G$5:$G$60,$A$5:$A$60,$A17,$H$5:$H$60,"Yes")=_xlfn.MINIFS($G$5:$G$60,$A$5:$A$60,$A17,$H$5:$H$60,"Yes"),1,($G17-_xlfn.MINIFS($G$5:$G$60,$A$5:$A$60,$A17,$H$5:$H$60,"Yes"))/(_xlfn.MAXIFS($G$5:$G$60,$A$5:$A$60,$A17,$H$5:$H$60,"Yes")-_xlfn.MINIFS($G$5:$G$60,$A$5:$A$60,$A17,$H$5:$H$60,"Yes"))),$G17/5)) -> 0.72 | P17: =IF(OR($H17<>"Yes",$M17=""),"",IF(_xlfn.MAXIFS($M$5:$M$60,$A$5:$A$60,$A17,$H$5:$H$60,"Yes")=_xlfn.MINIFS($M$5:$M$60,$A$5:$A$60,$A17,$H$5:$H$60,"Yes"),1,($M17-_xlfn.MINIFS($M$5:$M$60,$A$5:$A$60,$A17,$H$5:$H$60,"Yes"))/(_xlfn.MAXIFS($M$5:$M$60,$A$5:$A$60,$A17,$H$5:$H$60,"Yes")-_xlfn.MINIFS($M$5:$M$60,$A$5:$A$60,$A17,$H$5:$H$60,"Yes")))) -> 1 | Q17: =IF(OR($H17<>"Yes",$J17=""),"",IF(_xlfn.MAXIFS($J$5:$J$60,$A$5:$A$60,$A17,$H$5:$H$60,"Yes")=_xlfn.MINIFS($J$5:$J$60,$A$5:$A$60,$A17,$H$5:$H$60,"Yes"),1,(_xlfn.MAXIFS($J$5:$J$60,$A$5:$A$60,$A17,$H$5:$H$60,"Yes")-$J17)/(_xlfn.MAXIFS($J$5:$J$60,$A$5:$A$60,$A17,$H$5:$H$60,"Yes")-_xlfn.MINIFS($J$5:$J$60,$A$5:$A$60,$A17,$H$5:$H$60,"Yes")))) | R17: =IF($H17<>"Yes","",IFERROR(ROUND(100*(IF($N17="",0,Weights!$B$5*$N17)+IF($O17="",0,Weights!$B$6*$O17)+IF($P17="",0,Weights!$B$7*$P17)+IF($Q17="",0,Weights!$B$8*$Q17))/(IF($N17="",0,Weights!$B$5)+IF($O17="",0,Weights!$B$6)+IF($P17="",0,Weights!$B$7)+IF($Q17="",0,Weights!$B$8)),2),"")) -> 41.6 | S17: =IF($R17="","",COUNTIFS($A$5:$A$60,$A17,$R$5:$R$60,">"&$R17)+1) -> 3 | T17: =IF(OR($H17<>"Yes",$E17=""),"",COUNTIFS($A$5:$A$60,$A17,$H$5:$H$60,"Yes",$E$5:$E$60,"<"&$E17)+1) -> 3 | U17: =IF($S17="","",$A17&"|"&$S17) -> 5|3 | V17: =IF($T17="","",$A17&"|"&$T17) -> 5|3 | W17: =IF($B17="","",$B17&"|"&$D17) -> Girls Cotton Party Frock|Amazon
A18: 5 | B18: Girls Cotton Party Frock | C18: Clothing | D18: Flipkart | E18: 314 | F18: No Warranty | G18: 3.9 | H18: Yes | I18: 46310 | K18: Open | L18: Image | M18: =IF($F18="","",IF(ISNUMBER(SEARCH("no warranty",$F18)),0,IF(ISNUMBER(SEARCH("year",$F18)),12*VALUE(LEFT($F18,FIND(" ",$F18)-1)),IF(ISNUMBER(SEARCH("month",$F18)),VALUE(LEFT($F18,FIND(" ",$F18)-1)),"")))) -> 0 | N18: =IF(OR($H18<>"Yes",$E18=""),"",IF(_xlfn.MAXIFS($E$5:$E$60,$A$5:$A$60,$A18,$H$5:$H$60,"Yes")=_xlfn.MINIFS($E$5:$E$60,$A$5:$A$60,$A18,$H$5:$H$60,"Yes"),1,(_xlfn.MAXIFS($E$5:$E$60,$A$5:$A$60,$A18,$H$5:$H$60,"Yes")-$E18)/(_xlfn.MAXIFS($E$5:$E$60,$A$5:$A$60,$A18,$H$5:$H$60,"Yes")-_xlfn.MINIFS($E$5:$E$60,$A$5:$A$60,$A18,$H$5:$H$60,"Yes")))) -> 0.83737864 | O18: =IF(OR($H18<>"Yes",$G18=""),"",IF(Weights!$B$10="Relative",IF(_xlfn.MAXIFS($G$5:$G$60,$A$5:$A$60,$A18,$H$5:$H$60,"Yes")=_xlfn.MINIFS($G$5:$G$60,$A$5:$A$60,$A18,$H$5:$H$60,"Yes"),1,($G18-_xlfn.MINIFS($G$5:$G$60,$A$5:$A$60,$A18,$H$5:$H$60,"Yes"))/(_xlfn.MAXIFS($G$5:$G$60,$A$5:$A$60,$A18,$H$5:$H$60,"Yes")-_xlfn.MINIFS($G$5:$G$60,$A$5:$A$60,$A18,$H$5:$H$60,"Yes"))),$G18/5)) -> 0.78 | P18: =IF(OR($H18<>"Yes",$M18=""),"",IF(_xlfn.MAXIFS($M$5:$M$60,$A$5:$A$60,$A18,$H$5:$H$60,"Yes")=_xlfn.MINIFS($M$5:$M$60,$A$5:$A$60,$A18,$H$5:$H$60,"Yes"),1,($M18-_xlfn.MINIFS($M$5:$M$60,$A$5:$A$60,$A18,$H$5:$H$60,"Yes"))/(_xlfn.MAXIFS($M$5:$M$60,$A$5:$A$60,$A18,$H$5:$H$60,"Yes")-_xlfn.MINIFS($M$5:$M$60,$A$5:$A$60,$A18,$H$5:$H$60,"Yes")))) -> 1 | Q18: =IF(OR($H18<>"Yes",$J18=""),"",IF(_xlfn.MAXIFS($J$5:$J$60,$A$5:$A$60,$A18,$H$5:$H$60,"Yes")=_xlfn.MINIFS($J$5:$J$60,$A$5:$A$60,$A18,$H$5:$H$60,"Yes"),1,(_xlfn.MAXIFS($J$5:$J$60,$A$5:$A$60,$A18,$H$5:$H$60,"Yes")-$J18)/(_xlfn.MAXIFS($J$5:$J$60,$A$5:$A$60,$A18,$H$5:$H$60,"Yes")-_xlfn.MINIFS($J$5:$J$60,$A$5:$A$60,$A18,$H$5:$H$60,"Yes")))) | R18: =IF($H18<>"Yes","",IFERROR(ROUND(100*(IF($N18="",0,Weights!$B$5*$N18)+IF($O18="",0,Weights!$B$6*$O18)+IF($P18="",0,Weights!$B$7*$P18)+IF($Q18="",0,Weights!$B$8*$Q18))/(IF($N18="",0,Weights!$B$5)+IF($O18="",0,Weights!$B$6)+IF($P18="",0,Weights!$B$7)+IF($Q18="",0,Weights!$B$8)),2),"")) -> 85.27 | S18: =IF($R18="","",COUNTIFS($A$5:$A$60,$A18,$R$5:$R$60,">"&$R18)+1) -> 2 | T18: =IF(OR($H18<>"Yes",$E18=""),"",COUNTIFS($A$5:$A$60,$A18,$H$5:$H$60,"Yes",$E$5:$E$60,"<"&$E18)+1) -> 2 | U18: =IF($S18="","",$A18&"|"&$S18) -> 5|2 | V18: =IF($T18="","",$A18&"|"&$T18) -> 5|2 | W18: =IF($B18="","",$B18&"|"&$D18) -> Girls Cotton Party Frock|Flipkart
